Workbook

Sheet Read me
A1: SeereonOS - Business Process Catalogue (v4)
A2: Seereon Consulting & IT Services Pvt. Ltd., Bhubaneswar | Prepared for Santosh Nayak, Founder & CEO | Version v4 | Version date: 1 Oct 2026
A4: Purpose
A5: This workbook is the master reference for how a company runs on SeereonOS: every business process, who does it, who approves it, which rules the system enforces, what data it captures, which KPIs it produces and which dashboards it feeds. The aim is a company that can run, grow and build itself on process and data: every task, appraisal, person's performance, revenue earned, revenue lost and additional expense tracked in one system.
A6: Status reflects the product as built on 1 Oct 2026 (release v4). Rows marked Planned are processes a complete company OS for an Indian IT services / SAP consulting firm (10-200 people) still needs, each with a one-line recommendation.
A8: What is new in v4
A9: - Maker-checker: sensitive changes (roles, user access, salaries / cost rates, payroll finalisation, vendor bank and tax details, approval workflows, organisation profile and more) are proposed by one person and applied only when a second person approves. See the Maker-checker sheet and processes MC-01..04.
A10: - Granular role-permission matrix: 72 permissions in 9 modules; roles are data per workspace. Default roles: Administrator, CEO, CTO, Project Manager, HR Manager, HR Executive, Sales Manager, Sales Executive, Employee. Per-person extra and revoked permissions on top of the role. See Roles & permissions and ACC-01..03.
A11: - One login: screens, actions and data scope follow effective permissions; the role's persona only picks the home dashboard (ACC-09). View as works for any role (ACC-08).
A12: - Admin-configurable master data: organisation profile, locations, departments, designations, grades & CTC bands, cost centres, shifts & assignment, email templates & sent log (ADM-01..06).
A13: - Configurable approval workflows for leave, expenses, purchase orders, vendor bills, timesheets and task reviews: steps, amount thresholds, SLA and escalation, with a test panel; defaults reproduce v3 (WF-01..03, Approval workflows sheet).
A14: - Onboarding flow: Administrator signs in > fills org master data > reviews roles & permissions > creates employees with role and reporting manager > welcome email with temporary credentials (outbox) > employee signs in, must set a password, sees their own portal (SET-01, ACC-04, ACC-05; Setup & onboarding flow sheet).
... A41: RACI legend
A42: R | B42: Responsible: does the work
A43: A | B43: Accountable / approves (shown in bold)
A44: C | B44: Consulted: gives input before or during
A45: I | B45: Informed: notified or sees the result
A46: (blank) | B46: Not involved
A48: Status legend
A49: Live | B49: In the product before v3
A50: Extended | B50: Existed and was extended in v3 or v4 (see the "v4:" note)
A51: New in v3 | B51: Added in v3
A52: New in v4 | B52: Added in v4
A53: Planned | B53: Not built yet; recommended
A55: Processes by domain and status (live formulas)
A56: Domain | B56: Live | C56: Extended | D56: New in v3 | E56: New in v4 | F56: Planned | G56: Total
A57: Workspace & access | B57: =COUNTIFS('Process catalogue'!$B$2:$B$186,$A57,'Process catalogue'!$AA$2:$AA$186,B$56) | C57: =COUNTIFS('Process catalogue'!$B$2:$B$186,$A57,'Process catalogue'!$AA$2:$AA$186,C$56) | D57: =COUNTIFS('Process catalogue'!$B$2:$B$186,$A57,'Process catalogue'!$AA$2:$AA$186,D$56) | E57: =COUNTIFS('Process catalogue'!$B$2:$B$186,$A57,'Process catalogue'!$AA$2:$AA$186,E$56) | F57: =COUNTIFS('Process catalogue'!$B$2:$B$186,$A57,'Process catalogue'!$AA$2:$AA$186,F$56) | G57: =SUM(B57:F57)
A58: Organisation & master data | B58: =COUNTIFS('Process catalogue'!$B$2:$B$186,$A58,'Process catalogue'!$AA$2:$AA$186,B$56) | C58: =COUNTIFS('Process catalogue'!$B$2:$B$186,$A58,'Process catalogue'!$AA$2:$AA$186,C$56) | D58: =COUNTIFS('Process catalogue'!$B$2:$B$186,$A58,'Process catalogue'!$AA$2:$AA$186,D$56) | E58: =COUNTIFS('Process catalogue'!$B$2:$B$186,$A58,'Process catalogue'!$AA$2:$AA$186,E$56) | F58: =COUNTIFS('Process catalogue'!$B$2:$B$186,$A58,'Process catalogue'!$AA$2:$AA$186,F$56) | G58: =SUM(B58:F58)
A59: Sales & CRM | B59: =COUNTIFS('Process catalogue'!$B$2:$B$186,$A59,'Process catalogue'!$AA$2:$AA$186,B$56) | C59: =COUNTIFS('Process catalogue'!$B$2:$B$186,$A59,'Process catalogue'!$AA$2:$AA$186,C$56) | D59: =COUNTIFS('Process catalogue'!$B$2:$B$186,$A59,'Process catalogue'!$AA$2:$AA$186,D$56) | E59: =COUNTIFS('Process catalogue'!$B$2:$B$186,$A59,'Process catalogue'!$AA$2:$AA$186,E$56) | F59: =COUNTIFS('Process catalogue'!$B$2:$B$186,$A59,'Process catalogue'!$AA$2:$AA$186,F$56) | G59: =SUM(B59:F59)
A60: Client & contract management | B60: =COUNTIFS('Process catalogue'!$B$2:$B$186,$A60,'Process catalogue'!$AA$2:$AA$186,B$56) | C60: =COUNTIFS('Process catalogue'!$B$2:$B$186,$A60,'Process catalogue'!$AA$2:$AA$186,C$56) | D60: =COUNTIFS('Process catalogue'!$B$2:$B$186,$A60,'Process catalogue'!$AA$2:$AA$186,D$56) | E60: =COUNTIFS('Process catalogue'!$B$2:$B$186,$A60,'Process catalogue'!$AA$2:$AA$186,E$56) | F60: =COUNTIFS('Process catalogue'!$B$2:$B$186,$A60,'Process catalogue'!$AA$2:$AA$186,F$56) | G60: =SUM(B60:F60)
A61: Project delivery | B61: =COUNTIFS('Process catalogue'!$B$2:$B$186,$A61,'Process catalogue'!$AA$2:$AA$186,B$56) | C61: =COUNTIFS('Process catalogue'!$B$2:$B$186,$A61,'Process catalogue'!$AA$2:$AA$186,C$56) | D61: =COUNTIFS('Process catalogue'!$B$2:$B$186,$A61,'Process catalogue'!$AA$2:$AA$186,D$56) | E61: =COUNTIFS('Process catalogue'!$B$2:$B$186,$A61,'Process catalogue'!$AA$2:$AA$186,E$56) | F61: =COUNTIFS('Process catalogue'!$B$2:$B$186,$A61,'Process catalogue'!$AA$2:$AA$186,F$56) | G61: =SUM(B61:F61)
A62: Task governance | B62: =COUNTIFS('Process catalogue'!$B$2:$B$186,$A62,'Process catalogue'!$AA$2:$AA$186,B$56) | C62: =COUNTIFS('Process catalogue'!$B$2:$B$186,$A62,'Process catalogue'!$AA$2:$AA$186,C$56) | D62: =COUNTIFS('Process catalogue'!$B$2:$B$186,$A62,'Process catalogue'!$AA$2:$AA$186,D$56) | E62: =COUNTIFS('Process catalogue'!$B$2:$B$186,$A62,'Process catalogue'!$AA$2:$AA$186,E$56) | F62: =COUNTIFS('Process catalogue'!$B$2:$B$186,$A62,'Process catalogue'!$AA$2:$AA$186,F$56) | G62: =SUM(B62:F62)
A63: Time & attendance | B63: =COUNTIFS('Process catalogue'!$B$2:$B$186,$A63,'Process catalogue'!$AA$2:$AA$186,B$56) | C63: =COUNTIFS('Process catalogue'!$B$2:$B$186,$A63,'Process catalogue'!$AA$2:$AA$186,C$56) | D63: =COUNTIFS('Process catalogue'!$B$2:$B$186,$A63,'Process catalogue'!$AA$2:$AA$186,D$56) | E63: =COUNTIFS('Process catalogue'!$B$2:$B$186,$A63,'Process catalogue'!$AA$2:$AA$186,E$56) | F63: =COUNTIFS('Process catalogue'!$B$2:$B$186,$A63,'Process catalogue'!$AA$2:$AA$186,F$56) | G63: =SUM(B63:F63)
A64: Documents & knowledge | B64: =COUNTIFS('Process catalogue'!$B$2:$B$186,$A64,'Process catalogue'!$AA$2:$AA$186,B$56) | C64: =COUNTIFS('Process catalogue'!$B$2:$B$186,$A64,'Process catalogue'!$AA$2:$AA$186,C$56) | D64: =COUNTIFS('Process catalogue'!$B$2:$B$186,$A64,'Process catalogue'!$AA$2:$AA$186,D$56) | E64: =COUNTIFS('Process catalogue'!$B$2:$B$186,$A64,'Process catalogue'!$AA$2:$AA$186,E$56) | F64: =COUNTIFS('Process catalogue'!$B$2:$B$186,$A64,'Process catalogue'!$AA$2:$AA$186,F$56) | G64: =SUM(B64:F64)
A65: People & HR | B65: =COUNTIFS('Process catalogue'!$B$2:$B$186,$A65,'Process catalogue'!$AA$2:$AA$186,B$56) | C65: =COUNTIFS('Process catalogue'!$B$2:$B$186,$A65,'Process catalogue'!$AA$2:$AA$186,C$56) | D65: =COUNTIFS('Process catalogue'!$B$2:$B$186,$A65,'Process catalogue'!$AA$2:$AA$186,D$56) | E65: =COUNTIFS('Process catalogue'!$B$2:$B$186,$A65,'Process catalogue'!$AA$2:$AA$186,E$56) | F65: =COUNTIFS('Process catalogue'!$B$2:$B$186,$A65,'Process catalogue'!$AA$2:$AA$186,F$56) | G65: =SUM(B65:F65)
A66: Payroll & compensation | B66: =COUNTIFS('Process catalogue'!$B$2:$B$186,$A66,'Process catalogue'!$AA$2:$AA$186,B$56) | C66: =COUNTIFS('Process catalogue'!$B$2:$B$186,$A66,'Process catalogue'!$AA$2:$AA$186,C$56) | D66: =COUNTIFS('Process catalogue'!$B$2:$B$186,$A66,'Process catalogue'!$AA$2:$AA$186,D$56) | E66: =COUNTIFS('Process catalogue'!$B$2:$B$186,$A66,'Process catalogue'!$AA$2:$AA$186,E$56) | F66: =COUNTIFS('Process catalogue'!$B$2:$B$186,$A66,'Process catalogue'!$AA$2:$AA$186,F$56) | G66: =SUM(B66:F66)
A67: Finance | B67: =COUNTIFS('Process catalogue'!$B$2:$B$186,$A67,'Process catalogue'!$AA$2:$AA$186,B$56) | C67: =COUNTIFS('Process catalogue'!$B$2:$B$186,$A67,'Process catalogue'!$AA$2:$AA$186,C$56) | D67: =COUNTIFS('Process catalogue'!$B$2:$B$186,$A67,'Process catalogue'!$AA$2:$AA$186,D$56) | E67: =COUNTIFS('Process catalogue'!$B$2:$B$186,$A67,'Process catalogue'!$AA$2:$AA$186,E$56) | F67: =COUNTIFS('Process catalogue'!$B$2:$B$186,$A67,'Process catalogue'!$AA$2:$AA$186,F$56) | G67: =SUM(B67:F67)
A68: Spend & procurement | B68: =COUNTIFS('Process catalogue'!$B$2:$B$186,$A68,'Process catalogue'!$AA$2:$AA$186,B$56) | C68: =COUNTIFS('Process catalogue'!$B$2:$B$186,$A68,'Process catalogue'!$AA$2:$AA$186,C$56) | D68: =COUNTIFS('Process catalogue'!$B$2:$B$186,$A68,'Process catalogue'!$AA$2:$AA$186,D$56) | E68: =COUNTIFS('Process catalogue'!$B$2:$B$186,$A68,'Process catalogue'!$AA$2:$AA$186,E$56) | F68: =COUNTIFS('Process catalogue'!$B$2:$B$186,$A68,'Process catalogue'!$AA$2:$AA$186,F$56) | G68: =SUM(B68:F68)
... A73: Access, master data & controls | B73: =COUNTIFS('Process catalogue'!$B$2:$B$186,$A73,'Process catalogue'!$AA$2:$AA$186,B$56) | C73: =COUNTIFS('Process catalogue'!$B$2:$B$186,$A73,'Process catalogue'!$AA$2:$AA$186,C$56) | D73: =COUNTIFS('Process catalogue'!$B$2:$B$186,$A73,'Process catalogue'!$AA$2:$AA$186,D$56) | E73: =COUNTIFS('Process catalogue'!$B$2:$B$186,$A73,'Process catalogue'!$AA$2:$AA$186,E$56) | F73: =COUNTIFS('Process catalogue'!$B$2:$B$186,$A73,'Process catalogue'!$AA$2:$AA$186,F$56) | G73: =SUM(B73:F73)
A74: Total | B74: =SUM(B57:B73) | C74: =SUM(C57:C73) | D74: =SUM(D57:D73) | E74: =SUM(E57:E73) | F74: =SUM(F57:F73) | G74: =SUM(G57:G73)
...

Sheet Process catalogue
A1: ID | B1: Domain | C1: Sub-domain | D1: Process | E1: Purpose (why the business needs it) | F1: Trigger | G1: Steps | H1: Administrator | I1: CEO | J1: CTO | K1: Project Manager | L1: HR Manager | M1: HR Executive | N1: Sales Manager | O1: Sales Executive | P1: Employee | Q1: Line manager | R1: Platform SA | S1: Client | T1: Validations & business rules | U1: Data captured | V1: KPIs produced | W1: Dashboards / reports fed | X1: Notifications | Y1: Screen / route | Z1: Permission (v4) | AA1: Status | AB1: Notes / gaps
A2: WS-01 | B2: Workspace & access | C2: Tenancy | D2: Company sign-up and 14-day trial | E2: Lets a new company start using SeereonOS on its own, with its own isolated workspace. | F2: A company decides to try SeereonOS | G2: 1. Enter company name, your name, work email and password 2. Workspace is created with you as admin and a 14-day trial (up to 25 people) 3. Land on the onboarding checklist | H2: R | I2: I | R2: I | T2: Company and name required; valid work email; PASSWORD_WEAK (min 10 characters); USER_EMAIL_TAKEN. Trial = 14 days, 25-person cap. | U2: tenants, users, subscriptions (plan trial, status trialing) | V2: Tenant count, trials (platform) | W2: Platform tenant list | X2: NTF-11 trial ends in 3 days (catalogue only) | Y2: /signup | Z2: - | AA2: Extended | AB2: NTF-11 is defined in the spec but not raised by the product yet. v4: sign-up now provisions the nine default roles, organisation master data, the six approval workflows, system email templates and maker-checker (preselected, off) for the new workspace. The signer becomes Administrator.
A3: WS-02 | B3: Workspace & access | C3: Tenancy | D3: Onboarding checklist and sample data | E3: Gets a new workspace to first value fast: rules, calendar, people, first project, first timesheet week. | F3: First login after sign-up | G3: 1. Admin sees the checklist on Home: company settings, holidays, invite people, first project, first week 2. Optionally load sample data into an empty workspace 3. Dismiss or restore the checklist | H3: R | I3: I | L3: C | M3: I | T3: SAMPLE_NOT_EMPTY: sample data loads only into an empty workspace. | U3: onboarding state per tenant | V3: Setup completion | W3: CEO Home (onboarding card) | X3: - | Y3: /home, /onboarding | Z3: master.view | AA3: Extended | AB3: v4: superseded by the Setup checklist (SET-01, /setup) - org data, roles, workflows, people, emails.
A4: WS-03 | B4: Workspace & access | C4: Access | D4: Sign in, lockout and password reset | E4: Keeps accounts safe while letting people recover access themselves. | F4: Any user opens the app or forgets a password | G4: 1. Sign in with email and password 2. After 5 failed attempts the account locks for 15 minutes 3. Request a reset link (always accepted, link valid 60 minutes) 4. Set a new password | H4: R | I4: R | J4: R | K4: R | L4: R | M4: R | N4: R | O4: R | P4: R | R4: R | T4: LOGIN_FAILED (attempts left shown); LOGIN_LOCKED (security.lockout_attempts 5 / lockout_minutes 15); USER_DEACTIVATED; TENANT_SUSPENDED; RESET_EXPIRED; PASSWORD_WEAK (security.password_min_length 10). | U4: users.last_login_at, password reset tokens | V4: - | W4: - | X4: NTF-01 password reset (email) | Y4: /login, /reset-password | Z4: - | AA4: Extended | AB4: v4: one login for every role; screens and actions follow effective permissions (ACC-09). A temporary password forces a password change first (ACC-05, PASSWORD_CHANGE_REQUIRED).
A5: WS-04 | B5: Workspace & access | C5: People | D5: Invite people (single or bulk CSV) and accept invitation | E5: Brings every employee into the system with the right role and manager from day one. | F5: New joiner, or initial roll-out | G5: 1. Admin enters name, email, role and reports-to (or pastes CSV: name,email,role,reports_to_email; max 200 rows) 2. Invite link is emailed (valid 7 days); resend or revoke while pending 3. Invitee opens link, sets name and password, lands on their role dashboard | H5: R | I5: I | L5: A | M5: R | P5: R | Q5: I | T5: USER_EMAIL_TAKEN; SEATS_FULL (trial 25 people or paid seats); bulk import is all-or-nothing (any row error = nothing invited); INVITE_ACCEPTED (cannot revoke accepted); INVITE_EXPIRED; PASSWORD_WEAK. | U5: invites (email, name, role, reports_to_id, token, expires_at, accepted_at), users | V5: Headcount, pending invites | W5: People list; HR dashboard headcount | X5: NTF-02 invited (email) | Y5: /people, /invite/:token | Z5: R: (none); A: employees.create | AA5: Extended | AB5: Hiring a candidate creates the invite automatically (see HR-05). v4: superseded by Create employee (ACC-04) for single hires; invitations remain for bulk CSV and for hired candidates (HR-05). Gated by employees.create.
A6: WS-05 | B6: Workspace & access | C6: People | D6: Roles, reporting lines and access grants | E6: Decides who sees and approves what: the reports-to line drives timesheet, leave, expense and task approvals. | F6: Joiner, promotion, team change | G6: 1. Admin opens People and edits role (Admin, Project manager, Sales, HR & operations, Employee), reports-to and department 2. Optionally grant "margins" (PMs) or "salaries" (PMs, HR & operations) 3. Change takes effect immediately for approvals and visibility | H6: R | I6: A | J6: I | L6: C | P6: I | Q6: C | T6: LAST_ADMIN (at least one active admin); USER_REPORTS_LOOP (no self or circular reporting); GRANT_UNUSED warning; BR-07 approver = reports-to or active delegate; top person auto-approved. | U6: users (role, reports_to_id, department, grants) | V6: Span of control | W6: Team, Approvals inbox routing | X6: - | Y6: /people | Z6: users.manage | AA6: Extended | AB6: v4: the five hard-coded roles and grants are replaced by roles as data (ACC-01) and per-user extra / revoked permissions (ACC-03); grants "margins" / "salaries" became margins.view / cost_rates.view; LAST_ADMIN became LOCKOUT; role and access changes are maker-checked in Seereon.
A7: WS-06 | B7: Workspace & access | C7: People | D7: Approval delegation (cover during leave) | E7: Approvals never stall when a manager is away. | F7: Manager goes on leave or travel | G7: 1. Choose the delegate, from and to dates and a short reason 2. Delegate sees the manager's timesheet and leave approvals in their inbox for that period 3. Delete the delegation early if plans change | I7: R | J7: R | K7: R | Q7: R | T7: Admin, PM, HR & operations and Sales line managers can delegate (delegations.manage). Delegate must be active and not the delegator; both dates required; end on/after start and not in the past; reason min 3 characters; DELEGATION_OVERLAP. | U7: delegations (from_user_id, to_user_id, from_on, to_on, reason) | V7: Approval KPI stays clean | W7: Approvals inbox | X7: NTF-04 copies to delegate (leave) | Y7: /settings/delegations | Z7: delegations.manage | AA7: Extended | AB7: v3 opens delegation to HR & operations and Sales line managers (previously Admin and PM only).
A8: WS-07 | B8: Workspace & access | C8: People | D8: View as another role | E8: Lets the CEO check exactly what each role sees before rolling out. | F8: Admin wants to verify a role view | G8: 1. Admin picks "View as" a role or person 2. App shows that view with a read-only banner 3. Exit view-as to return | H8: R | I8: I | T8: All writes return 403 while view-as is active (enforced by the server). | U8: - | V8: - | W8: - | X8: - | Y8: Top bar (admin) | Z8: view_as | AA8: Extended | AB8: v4: any role, including custom roles, can be previewed; needs view_as (ACC-08).
A9: WS-08 | B9: Workspace & access | C9: Access | D9: Security, two-step verification and personal settings | E9: Protects admin accounts and lets each person manage their own profile and sessions. | F9: User setup or company security policy | G9: 1. Turn on two-step verification (TOTP) with a 6-digit code 2. Review and end other sessions 3. Change password, profile, avatar and theme preference 4. Admin can require 2FA for admins and set company theme/logo | H9: R | I9: A | J9: R | K9: R | L9: R | M9: R | N9: R | O9: R | P9: R | Q9: R | R9: R | T9: TWO_FACTOR_CODE; TWO_FACTOR_REQUIRED (security.require_2fa_admins); TWO_FACTOR_PENDING warning; PASSWORD_WRONG; session idle 60 min; logo PNG/SVG/JPG/WebP up to 1 MB (FILE_REJECTED); colours must be hex. | U9: users.two_factor, sessions, prefs, tenant.theme, logo | V9: - | W9: - | X9: - | Y9: /settings/security, /settings/profile, /settings/appearance | Z9: R: (none); A: settings.edit | AA9: Live | AB9: -
A10: WS-09 | B10: Workspace & access | C10: People | D10: Deactivate or reactivate a person | E10: Removes access on exit without losing their history, hours or approvals. | F10: Exit completed, or re-joining | G10: 1. Admin deactivates the person (or the exit checklist does it after the last day) 2. Their reports are flagged to be re-assigned 3. Reactivate if they return | H10: R | I10: I | L10: A | M10: C | Q10: C | T10: LAST_ADMIN (cannot deactivate yourself or the last admin); REPORTS_ORPHANED warning; deactivated users cannot sign in (USER_DEACTIVATED). | U10: users.status | V10: Headcount, attrition | W10: HR dashboard | X10: - | Y10: /people | Z10: employees.deactivate | AA10: Extended | AB10: v4: needs employees.deactivate; PERMISSION_ESCALATION and LOCKOUT protect access administrators; maker-checked when "Employee creation & deactivation" is on (ACC-07).
A11: WS-10 | B11: Workspace & access | C11: Data | D11: Full data export | E11: The company owns its data and can take a complete copy at any time. | F11: Audit, backup or migration | G11: 1. Admin requests an export 2. System prepares it and notifies when ready 3. Download within 24 hours | H11: R | I11: I | T11: RATE_LIMITED (several exports in a minute); EXPORT_EXPIRED after 24 hours. | U11: data_exports | V11: - | W11: - | X11: NTF-17 export ready | Y11: /settings/data | Z11: data.export | AA11: Live | AB11: -
A12: WS-11 | B12: Workspace & access | C12: Subscription | D12: Plan, seats and payment | E12: Pays for SeereonOS per user and keeps seats in line with headcount. | F12: Trial ending, or headcount change | G12: 1. Admin compares plans (Starter Rs 399, Growth Rs 499, Scale Rs 699 per user per month + 18% GST) 2. Choose seats and pay by card or UPI (Razorpay) 3. Add seats later; download billing invoices | H12: R | I12: I | R12: I | T12: SEATS_BELOW_USAGE (seats cannot be below people + pending invites); PLAN_LIMIT; PAYMENT_FAILED; read-only tenant can open Billing only, everything else returns 402 TENANT_READ_ONLY. | U12: subscriptions, billing_invoices | V12: Seat usage | W12: Billing | X12: NTF-16 payment failed | Y12: /billing | Z12: billing.manage | AA12: Live | AB12: -
A13: WS-12 | B13: Workspace & access | C13: Platform | D13: Platform tenant administration | E13: Lets SeereonOS operations support customers without ever seeing their business data. | F13: Support request, trial extension, non-payment | G13: 1. Platform admin opens the tenant list 2. Extend a trial by 1-30 days, suspend or reactivate with a reason 3. Every action is audited | R13: R | T13: Reason min 5 characters (audited); extend 1-30 days; TENANT_ACTIVE (paid tenants have no trial); TENANT_SUSPENDED. | U13: tenants.status, trial_ends_on | V13: Active tenants, trials | W13: Platform tenant list | X13: - | Y13: /admin | Z13: - | AA13: Live | AB13: -
A14: WS-13 | B14: Workspace & access | C14: Access | D14: Single sign-on and custom roles | E14: Larger customers expect Google / Microsoft login and roles beyond the five built-in ones. | F14: Enterprise customer onboarding | G14: 1. Admin connects Google Workspace or Microsoft Entra ID 2. People sign in with company accounts; password login optional 3. Admin clones a built-in role and adjusts permissions | H14: R | I14: I | L14: C | M14: I | P14: I | R14: C | T14: - | U14: - | V14: - | W14: - | X14: - | Y14: - | Z14: - (planned) | AA14: Planned | AB14: Recommendation: add Google/Microsoft SSO first (most Indian IT firms use Google Workspace); custom roles after (spec future scope). v4: custom roles are delivered (ACC-01, ACC-02). Recommendation stands for Google / Microsoft SSO.
A15: ORG-01 | B15: Organisation & master data | C15: Company rules | D15: Company rules and settings | E15: Sets the rules every calculation uses: working hours, approval SLA, margin floor, pay rules, security. | F15: Set-up, or a policy change | G15: 1. Admin opens Company settings 2. Edit company name, time zone, FY start, weekly off, Saturday rule, min/max hours, timesheet step, SLA, margin floor, stale-deal days, pay rules, AI on/off 3. Save (each setting shows its effect inline) | H15: R | I15: I | J15: C | K15: C | L15: C | M15: I | T15: Every setting has a fixed range (e.g. min hours 1-12, SLA 1-10 days, variable 0-50%); max hours >= min hours; Saturdays off must be 1st-5th; STALE if someone else saved first. | U15: tenant.settings (calendar.*, timesheet.*, approval.*, pay.*, projects.*, allocation.*, sales.*, security.*, ai.enabled) | V15: Drives all KPIs | W15: All | X15: - | Y15: /settings/company | Z15: settings.edit | AA15: Extended | AB15: v4: "Company settings" is listed as a maker-checker change type, but saving company settings applies directly in this build (not routed through propose).
A16: ORG-02 | B16: Organisation & master data | C16: Calendar | D16: Working calendar and holidays | E16: Defines working days, which drive costs, SLAs, timeliness, leave and pay. | F16: Start of year, or a new holiday announced | G16: 1. Admin adds holidays one by one or imports CSV (date,name[,optional]) 2. Edit or delete a holiday 3. Calendar applies to timesheets, SLA, payroll and task timeliness | H16: R | I16: I | L16: R | M16: I | P16: I | T16: BR-01 working day = not weekly off, not holiday, not approved leave; BR-02 Sunday off, Saturday rule; HOLIDAY_EXISTS; CSV import all-or-nothing; PAYROLL_FINAL warning if month already paid. | U16: holidays (date, name, optional) | V16: Working days per month | W16: Timesheet, Leave, Payroll | X16: - | Y16: /settings/holidays | Z16: holidays.edit | AA16: Extended | AB16: One calendar per company; location-wise calendars are future scope. v4: HR Manager can maintain holidays (holidays.edit).
A17: ORG-03 | B17: Organisation & master data | C17: Cost | D17: Cost rates (CTC history) | E17: Turns every approved hour into cost, so project margins and payroll are exact. | F17: Joining, increment (auto-created when an appraisal with an increment is completed), or correction | G17: 1. Admin adds a rate: monthly CTC, variable %, sales target, effective-from 2. History is append-only; the rate valid on each work date is used 3. Future rates can be removed | H17: C | I17: A | L17: C | T17: BR-23 cost/hour = monthly CTC / (working days x min hours); MONEY_INVALID; variable 0-50%; RATE_PERIOD_LOCKED (month already paid, or not after latest); RATE_EXISTS; RATE_BACKDATED warning. | U17: cost_rates (user_id, monthly_ctc_paise, variable_pct, sales_target_paise, effective_from) | V17: Cost per hour, project cost, margin | W17: Project money tab, P&L, Payroll | X17: - | Y17: /settings/cost-rates | Z17: cost_rates.edit | AA17: Extended | AB17: v4: visible to holders of cost_rates.view (CEO, Administrator, HR Manager by default). Salary / cost-rate changes are maker-checked in Seereon (entity cost_rate, needs cost_rates.edit). Only CEO and Administrator hold cost_rates.edit, so one proposes and the other checks. Create employee can carry a CTC (CTC_NEEDS_APPROVAL when salaries are checked).
A18: ORG-04 | B18: Organisation & master data | C18: Vendors | D18: Vendor master (onboard, block, unblock) | E18: One verified list of suppliers so purchases and bills are clean and GST-compliant. | F18: New supplier, or a supplier problem | G18: 1. Admin / HR & operations adds vendor: name, category, GSTIN, PAN, contact, payment terms 2. Block a vendor with a reason; unblock when resolved 3. Blocked vendors cannot get new POs | I18: A | L18: R | M18: I | T18: DUPLICATE_VENDOR; VAL_GSTIN (15 characters, valid structure); VAL_PAN (10 characters, must match GSTIN chars 3-12); payment terms 0-180 days; block reason min 5 characters. | U18: vendors (name, category, gstin, pan, contact, payment_terms_days, status) | V18: Vendor count, spend by vendor | W18: Purchases & vendors | X18: - | Y18: /purchases (Vendors tab) | Z18: procurement.manage | AA18: Extended | AB18: New in v3. v4: adding a vendor, or changing its tax or bank details, is maker-checked in Seereon (entity vendor, needs procurement.manage); other vendor edits apply directly.
A19: ORG-05 | B19: Organisation & master data | C19: Catalogues | D19: Product, category and service catalogue maintenance | E19: Lets each company define its own products, ledger categories and ops categories. | F19: New product launch or new cost head | G19: 1. Admin edits products used in Sales, ledger income/expense categories and ops areas 2. Retire old entries without breaking history | H19: R | I19: I | L19: C | M19: I | N19: C | O19: C | T19: - | U19: - | V19: - | W19: - | X19: - | Y19: - | Z19: - (planned) | AA19: Planned | AB19: Today products (EduReon, SeerHR, LeadSync, Munim AI, MineReon, SAP consulting, Custom software) and categories are fixed in code. Recommendation: make them tenant-editable (spec F-SET-03).
A20: ORG-06 | B20: Organisation & master data | C20: Entities | D20: Multi-entity and multi-currency | E20: Needed once Seereon bills overseas clients (AlUla, ZooPlus) in USD/SAR/EUR or opens a second legal entity. | F20: Foreign client or new entity | G20: 1. Define legal entities with their own GSTIN and books 2. Record invoices and payments in client currency with an exchange rate 3. Consolidate P&L in INR | I20: A | N20: C | O20: C | T20: - | U20: - | V20: - | W20: - | X20: - | Y20: - | Z20: - (planned) | AA20: Planned | AB20: Recommendation: start with currency on invoice + realised FX gain/loss; full multi-entity later (debt TD-A06).
A21: SAL-01 | B21: Sales & CRM | C21: Pipeline | D21: Lead capture | E21: Every opportunity is recorded with a value and an owner, so the pipeline is real. | F21: Enquiry, referral (e.g. BNI), event, cold call | G21: 1. Sales creates a deal: title, client, contact, product, source, value, MRR, expected close, owner 2. Deal starts in an open stage (Lead) 3. Client record is created automatically if new | I21: I | N21: A | O21: R | T21: Required fields; MONEY_INVALID (value >= 0); source and product from list; owner must be Sales or Admin; DEAL_STAGE (a new lead cannot start Won/Lost). | U21: deals (title, client, contact, phone, email, product, source, owner_id, stage, value_paise, mrr_paise, expected_close) | V21: Open value, new leads per week | W21: Sales Home, CEO Home, Scorecard (new leads) | X21: - | Y21: /sales | Z21: deals.edit_own | AA21: Live | AB21: -
A22: SAL-02 | B22: Sales & CRM | C22: Pipeline | D22: Qualification, demo, proposal and negotiation | E22: Moves deals through clear stages with a probability, so the forecast is weighted and honest. | F22: Deal progresses | G22: 1. Drag the deal on the kanban: Lead (10%) > Qualified (20%) > Demo (35%) > Proposal (50%) > Negotiation (70%) 2. Set the next step and date 3. Stage history is kept automatically | I22: I | N22: A | O22: R | S22: C | T22: DEAL_STAGE (valid stage); closed deals cannot be edited except by Admin. | U22: deals.stage, next_step_on; deal_stage_history | V22: Weighted pipeline, funnel | W22: Sales Home (pipeline by stage), CEO Home (revenue ahead) | X22: - | Y22: /sales, /sales/:id | Z22: deals.edit_own | AA22: Live | AB22: Proposals are logged as activities; there is no quotation document builder yet (see SAL-08).
A23: SAL-03 | B23: Sales & CRM | C23: Activity | D23: Log sales activities and next steps | E23: Proves follow-up effort and keeps deals from going quiet. | F23: Call, meeting, demo, email, proposal or follow-up done | G23: 1. Open the deal and log the activity type, date and what happened 2. Set the next step and its date 3. Last-activity date resets the stale clock | I23: I | N23: R | O23: R | T23: Type required; note min 3 characters; activities cannot be in the future (use next step for plans). | U23: deal_activities (deal_id, date, type, note, by) | V23: Activities per week (target 15), follow-ups overdue | W23: Sales Home (recent activity), Scorecard (activities, follow-ups) | X23: - | Y23: /sales/:id | Z23: deals.edit_own | AA23: Live | AB23: -
A24: SAL-04 | B24: Sales & CRM | C24: Closing | D24: Close won and create the project | E24: Hands a won deal straight to delivery with no re-typing, and credits the seller. | F24: Client confirms the order | G24: 1. Move the deal to Won (value must be above zero); won date is stamped 2. Click Create project: name, client, contract value, type, dates, PM 3. Project is linked to the deal; seller's achieved target updates | I24: I | J24: C | K24: C | N24: A | O24: R | T24: DEAL_STAGE (add value before Won); DEAL_HAS_PROJECT (one project per deal); only Admin can move a deal out of Won/Lost; BR-16 achieved = value of deals won that month by owner. | U24: deals.won_on, project_id; projects (deal_id) | V24: Won value, win rate, avg cycle days | W24: Sales Home, CEO Home, Compensation | X24: NTF-14 to PM (project assigned) | Y24: /sales/:id | Z24: deals.edit_own | AA24: Live | AB24: -
A25: SAL-05 | B25: Sales & CRM | C25: Closing | D25: Close lost with reason | E25: Every lost deal teaches something and is counted as lost revenue. | F25: Client declines or goes silent | G25: 1. Move the deal to Lost and record why 2. Deal value appears automatically in the Lost revenue register 3. Win rate updates | I25: I | N25: A | O25: R | T25: DEAL_STAGE: reason is mandatory ("that is how the win rate improves"); only Admin can reopen. | U25: deals.lost_on, lost_reason; deal_stage_history.reason | V25: Win rate = won / (won + lost); lost value by reason | W25: Sales performance, Lost revenue | X25: - | Y25: /sales | Z25: deals.edit_own | AA25: Extended | AB25: v3 adds the automatic lost-deal row in the Lost revenue register (REV-02).
A26: SAL-06 | B26: Sales & CRM | C26: Hygiene | D26: Stale deal follow-up | E26: Stops the pipeline from being inflated by dead deals. | F26: No activity for 14 days (sales.stale_deal_days) | G26: 1. System flags the deal stale and notifies the owner once a day 2. Owner logs an activity, or closes the deal 3. CEO sees stale deals and value at stake | I26: I | N26: R | O26: R | T26: Stale = open deal with no activity for sales.stale_deal_days (default 14). | U26: deals.last_activity_on | V26: Stale count, value at stake | W26: Insights > Stale deals, CEO Home, Sales Home (deals needing action) | X26: NTF-12 deal stale | Y26: /insights/stale_deals | Z26: deals.edit_own | AA26: Live | AB26: -
A27: SAL-07 | B27: Sales & CRM | C27: Performance | D27: Sales performance review | E27: Shows each seller's results against cost, so the sales team pays for itself. | F27: Monthly / quarterly review | G27: 1. Open Sales performance and choose the period 2. Review per person: open value, weighted value, won, win rate, days to close, activities, cost vs closed 3. Review 6-month target vs achieved | I27: I | N27: A | O27: R | Q27: C | T27: Admin sees all sellers; a seller sees only their own (sales.performance_own). | U27: deals, deal_activities, cost_rates | V27: Win rate, weighted pipeline, avg cycle days, cost vs closed, achievement % | W27: Sales performance, Sales Home | X27: - | Y27: /sales/performance | Z27: R: sales.performance_own; A: sales.performance_all | AA27: Live | AB27: -
A28: SAL-08 | B28: Sales & CRM | C28: Proposal | D28: Quotation and estimate builder | E28: Produces consistent, margin-safe quotes from a rate card and effort estimate. | F28: Deal reaches Proposal | G28: 1. Pick a template (fixed price, T&M, AMS retainer) and rate card 2. Estimate effort by phase/role; system shows cost, price and margin vs floor 3. Generate a branded PDF quote with GST; version it 4. On Won, convert the estimate into project milestones and budget | I28: I | J28: C | K28: C | N28: A | O28: R | S28: I | T28: - | U28: - | V28: - | W28: - | X28: - | Y28: - | Z28: - (planned) | AA28: Planned | AB28: Recommendation: high value for SAP consulting; reuse cost rates and the margin floor (25%) to block under-priced quotes.
A29: SAL-09 | B29: Sales & CRM | C29: Lead capture | D29: Web and email lead capture | E29: Captures website and email enquiries automatically so none are missed. | F29: Website form or enquiry email | G29: 1. Website form posts to SeereonOS 2. Lead created with source Website and auto-assigned owner 3. Owner notified to respond within a set time | I29: I | N29: R | O29: R | T29: - | U29: - | V29: - | W29: - | X29: - | Y29: - | Z29: - (planned) | AA29: Planned | AB29: Recommendation: a public form endpoint plus first-response SLA tracking.
A30: CLI-01 | B30: Client & contract management | C30: Clients | D30: Client master | E30: One record per client with commercial terms, so billing, health and history line up. | F30: Deal won, project created, or manual entry | G30: 1. Sales/Admin creates or edits the client: name, industry, country, GSTIN, billing address, contact, owner, payment terms 2. Clients are also created automatically from deals and projects 3. Status follows the data (prospect, active, dormant); churned is set by hand | I30: I | J30: I | K30: I | N30: A | O30: R | T30: VAL_REQUIRED name; DUPLICATE_CLIENT; VAL_GSTIN (15 characters, blank for overseas); VAL_EMAIL; payment terms 0-180 days; VAL_STATUS. | U30: clients (name, industry, country, gstin, billing_address, primary_contact, owner_id, status, payment_terms_days, health) | V30: Active clients, billed FY, outstanding | W30: Clients & contracts | X30: - | Y30: /clients, /clients/:id | Z30: clients.manage | AA30: New in v3 | AB30: -
A31: CLI-02 | B31: Client & contract management | C31: Contracts | D31: Contract register | E31: Keeps every MSA, SOW, AMC, licence, NDA and retainer with value, dates and file. | F31: Contract signed | G31: 1. Open the client and add a contract: title, type, value, start, end, renewal date, auto-renew, file 2. Link it to a project if relevant 3. Terminate when ended early; only drafts can be deleted | I31: I | J31: C | K31: C | N31: A | O31: R | S31: I | T31: Title and type required; VAL_AMOUNT >= 0; dates required; DATE_RANGE (end after start; renewal inside term); file up to 10 MB; CONTRACT_LOCKED (only drafts deleted); status draft/active/terminated, expiry computed. | U31: contracts (client_id, project_id, title, kind, value_paise, start_on, end_on, renewal_on, auto_renew, status, file_id) | V31: Contract value, renewals due | W31: Clients & contracts | X31: - | Y31: /clients/:id | Z31: clients.manage | AA31: New in v3 | AB31: -
A32: CLI-03 | B32: Client & contract management | C32: Contracts | D32: Contract renewal | E32: No AMC or licence renewal is missed: renewals are recurring revenue. | F32: Contract enters the 60-day renewal window | G32: 1. Contract shows as Expiring 60 days before renewal/end 2. Account owner is notified once 3. Renew for 1-60 months with new value (creates a linked new contract) or let it expire | I32: I | N32: A | O32: R | S32: C | T32: Renewal window 60 days; renew 1-60 months; INVALID_STATE (already renewed/terminated); VAL_AMOUNT. | U32: contracts (renewed_from, reminded_on) | V32: Renewals due in 60 days and their value | W32: Clients & contracts (renewals) | X32: NTF-13 contract renewal due | Y32: /clients | Z32: clients.manage | AA32: New in v3 | AB32: -
A33: CLI-04 | B33: Client & contract management | C33: Health | D33: Client health and 360 view | E33: Flags clients at risk before the relationship or the cash suffers. | F33: Continuous (recomputed on view) | G33: 1. System scores each client: overdue invoices + project health 2. Client page shows projects, invoices, billed FY, outstanding, overdue, contracts, deals and lost revenue 3. Owner acts on the reasons shown | I33: I | J33: I | K33: I | N33: A | O33: R | T33: At risk = invoice overdue > 60 days, or a project NPA / off track. Watch = any amount overdue, or a project at risk / on hold. Good otherwise. | U33: clients.health (computed), health_reasons | V33: Clients at risk, outstanding, leakage per client | W33: Clients & contracts, CEO (via clients) | X33: - | Y33: /clients/:id | Z33: clients.manage | AA33: New in v3 | AB33: -
A34: CLI-05 | B34: Client & contract management | C34: Client portal | D34: Client portal and deliverable sign-off | E34: Clients see progress and approve deliverables and change requests online, with a dated record. | F34: Milestone ready for acceptance, or CR raised | G34: 1. Client user logs in to a portal limited to their projects 2. Reviews milestone progress and documents 3. Accepts or rejects deliverables / CRs with comments; acceptance can trigger invoicing | I34: I | J34: R | K34: R | S34: R | T34: - | U34: - | V34: - | W34: - | X34: - | Y34: - | Z34: - (planned) | AA34: Planned | AB34: Today a money-free client view exists for the PM to share (DEL-10). Recommendation: extend it into a login-based portal with sign-off (spec future scope).
A35: CLI-06 | B35: Client & contract management | C35: Contracts | D35: Contract e-signature | E35: Speeds up SOW/NDA signing and stores the signed copy against the contract. | F35: Contract ready to sign | G35: 1. Send the contract for e-sign (Aadhaar e-sign / DocuSign-type provider) 2. Track status; signed PDF stored automatically 3. Contract becomes Active on signature | I35: I | N35: A | O35: R | S35: R | T35: - | U35: - | V35: - | W35: - | X35: - | Y35: - | Z35: - (planned) | AA35: Planned | AB35: Recommendation: integrate an Indian e-sign provider; keep the audit certificate with the contract.
A36: CLI-07 | B36: Client & contract management | C36: Satisfaction | D36: Customer satisfaction (CSAT / NPS) | E36: Measures how clients feel, not just what they pay; early warning for churn. | F36: Milestone accepted, project closed, or quarterly | G36: 1. System sends a short survey to the client contact 2. Scores and comments are stored on the client and project 3. Low scores alert the account owner and PM | I36: I | J36: C | K36: C | N36: R | O36: R | S36: R | T36: - | U36: - | V36: - | W36: - | X36: - | Y36: - | Z36: - (planned) | AA36: Planned | AB36: Recommendation: feed CSAT into client health and PM appraisals.
A37: DEL-01 | B37: Project delivery | C37: Set-up | D37: Create a project | E37: Every engagement gets a code, PM, value, billing model and plan, so hours and money link to it. | F37: Deal won, internal initiative, or AMS renewal | G37: 1. Admin/PM creates the project: name, client, type (Product, Service, SaaS, AMS), billing model (fixed, T&M, subscription, AMS retainer), revenue stream, PM, dates, contract value 2. Optionally add first milestones with end dates and billing amounts 3. Code is assigned automatically (PRJ-014 style) and the PM is notified | I37: I | J37: A | K37: R | N37: C | O37: C | T37: Type, billing model, stream, PM required; DATE_RANGE; milestone ends must run in order inside the project; MS_BILLING_OVER warning if milestone billing exceeds contract value; BR-18 types. | U37: projects (code, name, client, type, status, pm_id, start_on, end_on, contract_value_paise, billing_model, stream, deal_id, baseline_end_on) | V37: Active projects | W37: Projects list, CEO Home, PM Home | X37: NTF-14 "You manage PRJ-xxx" | Y37: /projects | Z37: projects.create | AA37: Live | AB37: -
A38: DEL-02 | B38: Project delivery | C38: Planning | D38: Milestones: plan, baseline and slip | E38: Milestones are the billing and delivery checkpoints; slips must be visible. | F38: Project planning or re-planning | G38: 1. PM adds milestones M1, M2... with planned start/end and billing amount 2. Baseline end is kept; moving a date shows the slip in days 3. Empty milestones are removed after 7 days unless invoiced | I38: I | J38: A | K38: R | P38: I | S38: I | T38: BR-19 numbering never reused; MS_OUTSIDE_PROJECT and MS_SLIP warnings; MS_BILLING_OVER warning; MS_INVOICED (billing amount fixed, cannot delete, BR-21); BR-20 empty milestone auto-deleted after projects.empty_milestone_days (7). | U38: milestones (no, name, planned_start, planned_end, baseline_end, billing_amount_paise, billing_status, achieved_on) | V38: Milestones on time %, slip days | W38: PM Home (upcoming milestones), CEO Home (milestones due 30 days) | X38: NTF-15 milestone auto-deleted / deleted | Y38: /projects/:id/wbs | Z38: projects.edit | AA38: Live | AB38: -
A39: DEL-03 | B39: Project delivery | C39: Planning | D39: Build the WBS (tasks, owners, estimates, dependencies) | E39: Breaks work into owned, estimated, dated tasks: the basis for timesheets, cost and timeliness. | F39: Project planning | G39: 1. PM adds tasks inline under a milestone (WBS code 2.3): title, owner, backup, estimate, start, due, complexity, priority, optional reviewer 2. Set dependencies between tasks 3. Owner is notified; tasks appear in My tasks | I39: I | J39: A | K39: R | P39: I | T39: Title under 200; estimate 0-999 h; DATE_RANGE; backup must differ from owner; TASK_SELF_REVIEW (reviewer is not the owner); DEP_CYCLE; dependencies same project; TASK_AFTER_MILESTONE warning; TASK_HAS_HOURS (cannot delete a task with logged hours). | U39: tasks (no, title, owner_id, backup_id, est_hours, start_on, due_on, complexity, priority, reviewer_id), task_dependencies | V39: Estimate, effort ratio, progress | W39: Project WBS, My tasks | X39: NTF-14 task assigned | Y39: /projects/:id/wbs | Z39: projects.edit|tasks.edit | AA39: Extended | AB39: v3 adds reviewer, priority and the review flow (TSK-05..10).
A40: DEL-04 | B40: Project delivery | C40: Planning | D40: Import a WBS from Excel/CSV | E40: Loads a full plan in minutes instead of typing it. | F40: New project with an existing plan | G40: 1. Download the template 2. Upload or paste the file; preview shows row errors 3. Commit: all rows or nothing; owners notified of their tasks | I40: I | J40: A | K40: R | P40: I | T40: WBS_INVALID (header missing, too many rows, preview expired, rows with errors); STALE if the WBS changed since preview. | U40: tasks, milestones | V40: - | W40: Project WBS | X40: NTF-14 (one per owner) | Y40: /projects/:id/import | Z40: projects.edit | AA40: Live | AB40: -
...

Sheet Role view
A1: Role | B1: Process ID | C1: Domain | D1: Process | E1: RACI | F1: What they actually do / see | G1: Screen / route | H1: Status
A2: Administrator | B2: WS-01 | C2: Workspace & access | D2: Company sign-up and 14-day trial | E2: R | F2: Does it: carries out "Company sign-up and 14-day trial" in /signup. | G2: /signup | H2: Extended
A3: Administrator | B3: WS-02 | C3: Workspace & access | D3: Onboarding checklist and sample data | E3: R | F3: Does it: carries out "Onboarding checklist and sample data" in /home, /onboarding. | G3: /home, /onboarding | H3: Extended
A4: Administrator | B4: WS-03 | C4: Workspace & access | D4: Sign in, lockout and password reset | E4: R | F4: Does it: carries out "Sign in, lockout and password reset" in /login, /reset-password. | G4: /login, /reset-password | H4: Extended
A5: Administrator | B5: WS-04 | C5: Workspace & access | D5: Invite people (single or bulk CSV) and accept invitation | E5: R | F5: Does it: carries out "Invite people (single or bulk CSV) and accept invitation" in /people, /invite/:token. | G5: /people, /invite/:token | H5: Extended
A6: Administrator | B6: WS-05 | C6: Workspace & access | D6: Roles, reporting lines and access grants | E6: R | F6: Does it: carries out "Roles, reporting lines and access grants" in /people. | G6: /people | H6: Extended
A7: Administrator | B7: WS-07 | C7: Workspace & access | D7: View as another role | E7: R | F7: Does it: carries out "View as another role" in Top bar (admin). | G7: Top bar (admin) | H7: Extended
A8: Administrator | B8: WS-08 | C8: Workspace & access | D8: Security, two-step verification and personal settings | E8: R | F8: Does it: carries out "Security, two-step verification and personal settings" in /settings/security, /settings/profile, /settings/appearance. | G8: /settings/security, /settings/profile, /settings/appearance | H8: Live
A9: Administrator | B9: WS-09 | C9: Workspace & access | D9: Deactivate or reactivate a person | E9: R | F9: Does it: carries out "Deactivate or reactivate a person" in /people. | G9: /people | H9: Extended
A10: Administrator | B10: WS-10 | C10: Workspace & access | D10: Full data export | E10: R | F10: Does it: carries out "Full data export" in /settings/data. | G10: /settings/data | H10: Live
A11: Administrator | B11: WS-11 | C11: Workspace & access | D11: Plan, seats and payment | E11: R | F11: Does it: carries out "Plan, seats and payment" in /billing. | G11: /billing | H11: Live
A12: Administrator | B12: WS-13 | C12: Workspace & access | D12: Single sign-on and custom roles | E12: R | F12: Planned (not built yet). Does it: carries out "Single sign-on and custom roles". | G12: - | H12: Planned
... A957: Client (external) | B957: OPS-04 | C957: Operations & compliance | D957: ISO 9001 non-conformance and CAPA | E957: C | F957: Planned (not built yet). Consulted: gives input, data or a decision when asked. | G957: - | H957: Planned

Sheet Roles & permissions
A1: Module | B1: Permission key | C1: Label | D1: Description | E1: Kind | F1: Sensitive | G1: Administrator | H1: CEO | I1: CTO | J1: Project Manager | K1: HR Manager | L1: HR Executive | M1: Sales Manager | N1: Sales Executive | O1: Employee | P1: Roles holding it
A2: My work (4)
A3: My work | B3: timesheet.own | C3: Log own timesheet | D3: Fill and submit weekly timesheets. | E3: create | G3: ✓ | H3: ✓ | I3: ✓ | J3: ✓ | K3: ✓ | L3: ✓ | M3: ✓ | N3: ✓ | O3: ✓ | P3: =COUNTIF(G3:O3,"✓")
A4: My work | B4: daily_update.post | C4: Post daily updates | D4: Post the daily stand-up update with proof. | E4: create | G4: ✓ | H4: ✓ | I4: ✓ | J4: ✓ | K4: ✓ | L4: ✓ | M4: ✓ | N4: ✓ | O4: ✓ | P4: =COUNTIF(G4:O4,"✓")
A5: My work | B5: approvals.act | C5: Act on own approvals | D5: Approve items routed to them (reports-to and workflow scope still apply). | E5: approve | G5: ✓ | H5: ✓ | I5: ✓ | J5: ✓ | K5: ✓ | L5: ✓ | M5: ✓ | N5: ✓ | O5: ✓ | P5: =COUNTIF(G5:O5,"✓")
A6: My work | B6: ai.use | C6: Use Ask AI | D6: Ask questions in plain language and build AI reports within their own data access. | E6: view | G6: ✓ | H6: ✓ | I6: ✓ | J6: ✓ | K6: ✓ | L6: ✓ | M6: ✓ | N6: ✓ | O6: ✓ | P6: =COUNTIF(G6:O6,"✓")
A7: Projects & delivery (11)
A8: Projects & delivery | B8: projects.view_all | C8: See all projects | D8: Every project in the company, not only the ones they work on. | E8: view | G8: ✓ | H8: ✓ | I8: ✓ | J8: ✓ | K8: ✓ | P8: =COUNTIF(G8:O8,"✓")
A9: Projects & delivery | B9: projects.create | C9: Create projects | D9: Start new projects and import a WBS. | E9: create | G9: ✓ | H9: ✓ | I9: ✓ | J9: ✓ | P9: =COUNTIF(G9:O9,"✓")
A10: Projects & delivery | B10: projects.edit | C10: Edit projects they manage | D10: Plan, milestones, status and team of projects where they are the PM. | E10: edit | G10: ✓ | H10: ✓ | I10: ✓ | J10: ✓ | P10: =COUNTIF(G10:O10,"✓")
A11: Projects & delivery | B11: projects.manage_all | C11: Manage every project | D11: Edit any project and its tasks, and hand a project to another project manager. | E11: manage | G11: ✓ | H11: ✓ | I11: ✓ | P11: =COUNTIF(G11:O11,"✓")
A12: Projects & delivery | B12: tasks.edit | C12: Plan and edit tasks | D12: Create, assign and reschedule project tasks. | E12: edit | G12: ✓ | H12: ✓ | I12: ✓ | J12: ✓ | P12: =COUNTIF(G12:O12,"✓")
A13: Projects & delivery | B13: tasks.status_any | C13: Change any task status | D13: Move tasks that are owned by someone else. | E13: edit | G13: ✓ | H13: ✓ | I13: ✓ | J13: ✓ | P13: =COUNTIF(G13:O13,"✓")
A14: Projects & delivery | B14: allocation.edit | C14: Allocate people | D14: Change allocation % of people on projects. | E14: edit | G14: ✓ | H14: ✓ | I14: ✓ | J14: ✓ | P14: =COUNTIF(G14:O14,"✓")
A15: Projects & delivery | B15: change_requests.manage | C15: Handle change requests | D15: Raise, price and close client change requests. | E15: manage | G15: ✓ | H15: ✓ | I15: ✓ | J15: ✓ | P15: =COUNTIF(G15:O15,"✓")
A16: Projects & delivery | B16: documents.manage | C16: Manage project documents | D16: Upload, version and archive project documents. | E16: manage | G16: ✓ | H16: ✓ | I16: ✓ | J16: ✓ | P16: =COUNTIF(G16:O16,"✓")
A17: Projects & delivery | B17: documents.view_all | C17: See all project documents | D17: Open documents of projects they are not on. | E17: view | G17: ✓ | H17: ✓ | I17: ✓ | P17: =COUNTIF(G17:O17,"✓")
A18: Projects & delivery | B18: openings.manage | C18: Manage openings | D18: Raise and track staffing openings. | E18: manage | G18: ✓ | H18: ✓ | I18: ✓ | J18: ✓ | K18: ✓ | L18: ✓ | P18: =COUNTIF(G18:O18,"✓")
A19: Team & performance (6)
A20: Team & performance | B20: team.view | C20: See team pages | D20: Team workload, timesheets and availability of their reports. | E20: view | G20: ✓ | H20: ✓ | I20: ✓ | J20: ✓ | K20: ✓ | M20: ✓ | P20: =COUNTIF(G20:O20,"✓")
A21: Team & performance | B21: tasks.assign_team | C21: Assign tasks to reports | D21: Give general tasks to people who report to them. | E21: create | G21: ✓ | H21: ✓ | I21: ✓ | J21: ✓ | K21: ✓ | M21: ✓ | P21: =COUNTIF(G21:O21,"✓")
A22: Team & performance | B22: tasks.review | C22: Review submitted tasks | D22: Approve or send back tasks where they are the reviewer. | E22: approve | G22: ✓ | H22: ✓ | I22: ✓ | J22: ✓ | K22: ✓ | M22: ✓ | P22: =COUNTIF(G22:O22,"✓")
A23: Team & performance | B23: tasks.analytics | C23: Task timeliness analytics | D23: Early / on-time / late completion and delay reasons across people. | E23: view | G23: ✓ | H23: ✓ | I23: ✓ | J23: ✓ | K23: ✓ | P23: =COUNTIF(G23:O23,"✓")
A24: Team & performance | B24: insights.view | C24: Insights & scorecards | D24: Manager dashboards and scorecards. | E24: view | G24: ✓ | H24: ✓ | I24: ✓ | J24: ✓ | K24: ✓ | M24: ✓ | N24: ✓ | P24: =COUNTIF(G24:O24,"✓")
A25: Team & performance | B25: delegations.manage | C25: Delegate approvals | D25: Hand approvals to someone else while away. | E25: manage | G25: ✓ | H25: ✓ | I25: ✓ | J25: ✓ | K25: ✓ | M25: ✓ | P25: =COUNTIF(G25:O25,"✓")
A26: People & HR (10)
A27: People & HR | B27: people.view_all | C27: See everyone’s HR records | D27: Profiles, leave and lifecycle of all employees. | E27: view | G27: ✓ | H27: ✓ | I27: ✓ | K27: ✓ | L27: ✓ | P27: =COUNTIF(G27:O27,"✓")
A28: People & HR | B28: people.manage | C28: Manage HR operations | D28: Lifecycle checklists, assets and leave policy. | E28: manage | G28: ✓ | H28: ✓ | K28: ✓ | P28: =COUNTIF(G28:O28,"✓")
A29: People & HR | B29: leave.approve | C29: Approve leave | D29: Approve leave for people in their approval scope. | E29: approve | G29: ✓ | H29: ✓ | I29: ✓ | J29: ✓ | K29: ✓ | M29: ✓ | P29: =COUNTIF(G29:O29,"✓")
A30: People & HR | B30: leave.hr_entry | C30: Record leave for others | D30: Enter leave on behalf of employees. | E30: edit | G30: ✓ | H30: ✓ | K30: ✓ | L30: ✓ | P30: =COUNTIF(G30:O30,"✓")
A31: People & HR | B31: appraisals.manage | C31: Run appraisals | D31: Open cycles, calibrate and close appraisals. | E31: manage | G31: ✓ | H31: ✓ | K31: ✓ | P31: =COUNTIF(G31:O31,"✓")
A32: People & HR | B32: recruitment.manage | C32: Recruitment | D32: Candidates, interviews and offers. | E32: manage | G32: ✓ | H32: ✓ | I32: ✓ | J32: ✓ | K32: ✓ | L32: ✓ | P32: =COUNTIF(G32:O32,"✓")
A33: People & HR | B33: cost_rates.view | C33: See salaries & cost rates | D33: CTC and cost per hour (read-only). | E33: sensitive | F33: Yes | G33: ✓ | H33: ✓ | K33: ✓ | P33: =COUNTIF(G33:O33,"✓")
A34: People & HR | B34: cost_rates.edit | C34: Change salaries & cost rates | D34: Set CTC and cost per hour. | E34: sensitive | F34: Yes | G34: ✓ | H34: ✓ | P34: =COUNTIF(G34:O34,"✓")
A35: People & HR | B35: payroll.run | C35: Prepare payroll | D35: Create and calculate monthly payroll runs. | E35: sensitive | F35: Yes | G35: ✓ | H35: ✓ | K35: ✓ | P35: =COUNTIF(G35:O35,"✓")
A36: People & HR | B36: payroll.finalise | C36: Finalise payroll | D36: Lock a payroll run and post it to the ledger. | E36: sensitive | F36: Yes | G36: ✓ | H36: ✓ | P36: =COUNTIF(G36:O36,"✓")
A37: Sales & clients (6)
A38: Sales & clients | B38: deals.view_all | C38: See all deals | D38: The whole pipeline, not only deals they own. | E38: view | G38: ✓ | H38: ✓ | M38: ✓ | P38: =COUNTIF(G38:O38,"✓")
A39: Sales & clients | B39: deals.edit_own | C39: Work own deals | D39: Create deals and move deals they own. | E39: edit | G39: ✓ | H39: ✓ | M39: ✓ | N39: ✓ | P39: =COUNTIF(G39:O39,"✓")
A40: Sales & clients | B40: deals.edit_all | C40: Edit any deal | D40: Reassign and edit anyone’s deals. | E40: manage | G40: ✓ | H40: ✓ | M40: ✓ | P40: =COUNTIF(G40:O40,"✓")
...

Sheet Maker-checker
A1: Change entity | B1: What it covers | C1: Group | D1: Required permission (checker also needs it) | E1: Who can make it (default roles) | F1: Who can check by default (Check changes + required permission) | G1: Seereon checkers today | H1: On in Seereon | I1: New tenants | J1: Recommended | K1: What is applied on approval | L1: Failure modes (approval fails or is refused) | M1: Screen
A2: Roles & permissions (role) | B2: Roles and their permission matrix | C2: Access | D2: roles.manage - Manage roles | E2: Administrator, CEO | F2: Administrator, CEO | G2: Debasish Mishra, Santosh Nayak | H2: Yes | I2: Preselected (maker-checker starts off) | J2: Yes | K2: Role created, edited (permissions, persona, name, active) or deleted; everyone holding it gets the new screens on their next request. | L2: STALE (role changed after proposal); ROLE_LOCKED; ROLE_IN_USE (delete / deactivate); LOCKOUT re-checked; ROLE_NAME_TAKEN. | M2: /setup/roles
A3: User access (role, extra permissions) (user_access) | B3: A person's role and extra / revoked permissions | C3: Access | D3: users.manage - Manage user access | E3: Administrator, CEO | F3: Administrator, CEO | G3: Debasish Mishra, Santosh Nayak | H3: Yes | I3: Preselected (maker-checker starts off) | J3: Yes | K3: Person's role, extra permissions and revoked permissions; effective permissions recomputed. | L3: STALE (their access changed meanwhile); role no longer exists; LOCKOUT; PERMISSION_ESCALATION at proposal. | M3: /people
A4: Employee creation & deactivation (employee) | B4: Creating an employee (with welcome email) and deactivating one | C4: Access | D4: employees.create - Create employees | E4: create: Administrator, CEO, HR Manager, HR Executive; deactivate: Administrator, CEO, HR Manager | F4: Administrator, CEO, HR Manager | G4: Debasish Mishra, Priya Mohapatra, Santosh Nayak | H4: No | I4: Not preselected | J4: No | K4: Create: user with employee code, temporary password, welcome email, CTC (if given). Deactivate: status deactivated, reports flagged. | L4: USER_EMAIL_TAKEN (created meanwhile); role inactive; SEATS_FULL; manager inactive; LOCKOUT on deactivation. | M4: /people/new, /people
A5: Salaries & cost rates (cost_rate) | B5: Monthly CTC, variable %, sales target | C5: Money | D5: cost_rates.edit - Change salaries & cost rates | E5: Administrator, CEO | F5: Administrator, CEO | G5: Debasish Mishra, Santosh Nayak | H5: Yes | I5: Preselected (maker-checker starts off) | J5: Yes | K5: CTC / variable % / sales target row added from its effective date, or a future row removed. | L5: STALE (rate history changed); RATE_PERIOD_LOCKED (month paid); RATE_EXISTS. | M5: /settings/cost-rates
A6: Payroll finalisation (payroll_finalise) | B6: Locking a monthly payroll run | C6: Money | D6: payroll.finalise - Finalise payroll | E6: Administrator, CEO, HR Manager | F6: Administrator, CEO | G6: Debasish Mishra, Santosh Nayak | H6: Yes | I6: Preselected (maker-checker starts off) | J6: Yes | K6: Run recomputed one last time, lines frozen, month locked for rates and holidays. | L6: STALE (run changed after the request); PAY_FINAL (already final). | M6: /payroll/:id
A7: Vendor bank & tax details (vendor) | B7: New vendors; vendor GSTIN, PAN and bank account | C7: Money | D7: procurement.manage - Procurement | E7: Administrator, CEO, HR Manager | F7: Administrator, CEO, HR Manager | G7: Debasish Mishra, Priya Mohapatra, Santosh Nayak | H7: Yes | I7: Preselected (maker-checker starts off) | J7: Yes | K7: New vendor, or a change of GSTIN, PAN or bank details (other vendor fields apply directly). | L7: STALE; DUPLICATE_VENDOR; VAL_GSTIN / VAL_PAN. | M7: /purchases (Vendors)
A8: Budgets (budget) | B8: Department / category budgets | C8: Money | D8: budgets.manage - Budgets | E8: Administrator, CEO | F8: Administrator, CEO | G8: Debasish Mishra, Santosh Nayak | H8: No | I8: Not preselected | J8: No | K8: Budget line set, deleted, or a year copied. | L8: STALE (budget changed meanwhile). | M8: /budgets
A9: Approval workflows (workflow) | B9: Approval workflow steps | C9: Configuration | D9: workflows.manage - Approval workflows | E9: Administrator, CEO | F9: Administrator, CEO | G9: Debasish Mishra, Santosh Nayak | H9: Yes | I9: Preselected (maker-checker starts off) | J9: Yes | K9: New steps for the process (or reset to default); requests already waiting keep their chain. | L9: STALE (workflow edited after proposal). | M9: /setup/workflows
A10: Organisation profile (org_profile) | B10: Legal identity, tax IDs, bank, employee code format | C10: Configuration | D10: master.edit - Edit master data | E10: Administrator, CEO, HR Manager | F10: Administrator, CEO, HR Manager | G10: Debasish Mishra, Priya Mohapatra, Santosh Nayak | H10: Yes | I10: Preselected (maker-checker starts off) | J10: Yes | K10: Organisation profile fields (legal, tax, address, bank, employee code). | L10: STALE; EMPLOYEE_CODE_TAKEN. | M10: /setup/org
