Workbook

Sheet Summary
A1: SeereonOS — Feature Guide cross-reference
A2: Seereon Delivery Board: Feature Guide (Santosh Nayak, 28 Sep 2026) checked against the SeereonOS v6 build
A3: Date | B3: 2 Oct 2026
A5: How to read this workbook
A6: Line-by-line check — every sentence, bullet and table row of the guide, verbatim and in order, with where you see it in the build and a Result (OK / OK — improved / Intentional difference / Different — open).
A7: Guide vs build — one row per Feature Guide item (118). 'In build?' shows Present / Intentional difference / Partial / Missing; 'Where in the build' gives the screen and route; 'Notes' flags improvements and intentional changes.
A8: Your columns — 'Checked by Santosh' (drop-down Yes / No / Query) and 'Comments' on 'Line-by-line check' and 'Guide vs build' are the only cells to fill in. Example: Yes · 'Checked on phone, fine'.
A9: Build feature list — every live feature of SeereonOS: guide features (one per G-ID) plus everything built in addition, with who can use it by default.
A10: Additional features — only the extras, each with one line on why it helps.
A11: Guide screenshots map — each of the 36 guide screenshots (000–035) mapped to the equivalent build screen.
A12: All counts below are live formulas: change a status on 'Guide vs build' and they update.
A14: Line-by-line check (every guide sentence)
A15: Guide lines checked (sentences, bullets, table rows) | B15: =COUNTA('Line-by-line check'!$E$5:$E$267)
A16: OK | B16: =COUNTIF('Line-by-line check'!$H$5:$H$267,"OK")
A17: OK — improved | B17: =COUNTIF('Line-by-line check'!$H$5:$H$267,"OK — improved")
A18: Intentional difference | B18: =COUNTIF('Line-by-line check'!$H$5:$H$267,"Intentional difference")
A19: Different — open | B19: =COUNTIF('Line-by-line check'!$H$5:$H$267,"Different — open")
A20: % matching or better (OK + improved) | B20: =IF(B15=0,0,(B16+B17)/B15)
A21: Checked by Santosh so far (Yes) | B21: =COUNTIF('Line-by-line check'!$J$5:$J$267,"Yes")
A22: Open queries | B22: =COUNTIF('Line-by-line check'!$J$5:$J$267,"Query")
A24: Guide coverage
A25: Guide features (total) | B25: =COUNTA('Guide vs build'!$B$5:$B$122)
A26: Present | B26: =COUNTIF('Guide vs build'!$E$5:$E$122,"Present")
A27: Intentional difference | B27: =COUNTIF('Guide vs build'!$E$5:$E$122,"Intentional difference")
A28: Partial | B28: =COUNTIF('Guide vs build'!$E$5:$E$122,"Partial")
A29: Missing | B29: =COUNTIF('Guide vs build'!$E$5:$E$122,"Missing")
A30: % covered (Present + intentional ÷ total) | B30: =IF(B25=0,0,(B26+B27)/B25)
A31: Checked by Santosh so far (Yes) | B31: =COUNTIF('Guide vs build'!$I$5:$I$122,"Yes")
A32: Open queries | B32: =COUNTIF('Guide vs build'!$I$5:$I$122,"Query")
A34: Coverage by guide section
A35: Guide section | B35: Features | C35: Present / intentional | D35: Partial | E35: Missing | F35: % covered
A36: 1. Roles and views | B36: =COUNTIF('Guide vs build'!$A$5:$A$122,$A36) | C36: =COUNTIFS('Guide vs build'!$A$5:$A$122,$A36,'Guide vs build'!$E$5:$E$122,"Present")+COUNTIFS('Guide vs build'!$A$5:$A$122,$A36,'Guide vs build'!$E$5:$E$122,"Intentional difference") | D36: =COUNTIFS('Guide vs build'!$A$5:$A$122,$A36,'Guide vs build'!$E$5:$E$122,"Partial") | E36: =COUNTIFS('Guide vs build'!$A$5:$A$122,$A36,'Guide vs build'!$E$5:$E$122,"Missing") | F36: =IF(B36=0,0,C36/B36)
A37: 2. CEO dashboard: revenue first | B37: =COUNTIF('Guide vs build'!$A$5:$A$122,$A37) | C37: =COUNTIFS('Guide vs build'!$A$5:$A$122,$A37,'Guide vs build'!$E$5:$E$122,"Present")+COUNTIFS('Guide vs build'!$A$5:$A$122,$A37,'Guide vs build'!$E$5:$E$122,"Intentional difference") | D37: =COUNTIFS('Guide vs build'!$A$5:$A$122,$A37,'Guide vs build'!$E$5:$E$122,"Partial") | E37: =COUNTIFS('Guide vs build'!$A$5:$A$122,$A37,'Guide vs build'!$E$5:$E$122,"Missing") | F37: =IF(B37=0,0,C37/B37)
A38: 3. Projects: list, status, type | B38: =COUNTIF('Guide vs build'!$A$5:$A$122,$A38) | C38: =COUNTIFS('Guide vs build'!$A$5:$A$122,$A38,'Guide vs build'!$E$5:$E$122,"Present")+COUNTIFS('Guide vs build'!$A$5:$A$122,$A38,'Guide vs build'!$E$5:$E$122,"Intentional difference") | D38: =COUNTIFS('Guide vs build'!$A$5:$A$122,$A38,'Guide vs build'!$E$5:$E$122,"Partial") | E38: =COUNTIFS('Guide vs build'!$A$5:$A$122,$A38,'Guide vs build'!$E$5:$E$122,"Missing") | F38: =IF(B38=0,0,C38/B38)
A39: 4. Project page: milestones, tasks and WBS | B39: =COUNTIF('Guide vs build'!$A$5:$A$122,$A39) | C39: =COUNTIFS('Guide vs build'!$A$5:$A$122,$A39,'Guide vs build'!$E$5:$E$122,"Present")+COUNTIFS('Guide vs build'!$A$5:$A$122,$A39,'Guide vs build'!$E$5:$E$122,"Intentional difference") | D39: =COUNTIFS('Guide vs build'!$A$5:$A$122,$A39,'Guide vs build'!$E$5:$E$122,"Partial") | E39: =COUNTIFS('Guide vs build'!$A$5:$A$122,$A39,'Guide vs build'!$E$5:$E$122,"Missing") | F39: =IF(B39=0,0,C39/B39)
A40: 5. Schedule, critical path and change requests | B40: =COUNTIF('Guide vs build'!$A$5:$A$122,$A40) | C40: =COUNTIFS('Guide vs build'!$A$5:$A$122,$A40,'Guide vs build'!$E$5:$E$122,"Present")+COUNTIFS('Guide vs build'!$A$5:$A$122,$A40,'Guide vs build'!$E$5:$E$122,"Intentional difference") | D40: =COUNTIFS('Guide vs build'!$A$5:$A$122,$A40,'Guide vs build'!$E$5:$E$122,"Partial") | E40: =COUNTIFS('Guide vs build'!$A$5:$A$122,$A40,'Guide vs build'!$E$5:$E$122,"Missing") | F40: =IF(B40=0,0,C40/B40)
A41: 6. Costing, allocation and margins | B41: =COUNTIF('Guide vs build'!$A$5:$A$122,$A41) | C41: =COUNTIFS('Guide vs build'!$A$5:$A$122,$A41,'Guide vs build'!$E$5:$E$122,"Present")+COUNTIFS('Guide vs build'!$A$5:$A$122,$A41,'Guide vs build'!$E$5:$E$122,"Intentional difference") | D41: =COUNTIFS('Guide vs build'!$A$5:$A$122,$A41,'Guide vs build'!$E$5:$E$122,"Partial") | E41: =COUNTIFS('Guide vs build'!$A$5:$A$122,$A41,'Guide vs build'!$E$5:$E$122,"Missing") | F41: =IF(B41=0,0,C41/B41)
A42: 7. Tasks: owners, dependencies, backup and threads | B42: =COUNTIF('Guide vs build'!$A$5:$A$122,$A42) | C42: =COUNTIFS('Guide vs build'!$A$5:$A$122,$A42,'Guide vs build'!$E$5:$E$122,"Present")+COUNTIFS('Guide vs build'!$A$5:$A$122,$A42,'Guide vs build'!$E$5:$E$122,"Intentional difference") | D42: =COUNTIFS('Guide vs build'!$A$5:$A$122,$A42,'Guide vs build'!$E$5:$E$122,"Partial") | E42: =COUNTIFS('Guide vs build'!$A$5:$A$122,$A42,'Guide vs build'!$E$5:$E$122,"Missing") | F42: =IF(B42=0,0,C42/B42)
A43: 8. Timesheet and daily update | B43: =COUNTIF('Guide vs build'!$A$5:$A$122,$A43) | C43: =COUNTIFS('Guide vs build'!$A$5:$A$122,$A43,'Guide vs build'!$E$5:$E$122,"Present")+COUNTIFS('Guide vs build'!$A$5:$A$122,$A43,'Guide vs build'!$E$5:$E$122,"Intentional difference") | D43: =COUNTIFS('Guide vs build'!$A$5:$A$122,$A43,'Guide vs build'!$E$5:$E$122,"Partial") | E43: =COUNTIFS('Guide vs build'!$A$5:$A$122,$A43,'Guide vs build'!$E$5:$E$122,"Missing") | F43: =IF(B43=0,0,C43/B43)
A44: 9. Approvals and the manager's approval KPI | B44: =COUNTIF('Guide vs build'!$A$5:$A$122,$A44) | C44: =COUNTIFS('Guide vs build'!$A$5:$A$122,$A44,'Guide vs build'!$E$5:$E$122,"Present")+COUNTIFS('Guide vs build'!$A$5:$A$122,$A44,'Guide vs build'!$E$5:$E$122,"Intentional difference") | D44: =COUNTIFS('Guide vs build'!$A$5:$A$122,$A44,'Guide vs build'!$E$5:$E$122,"Partial") | E44: =COUNTIFS('Guide vs build'!$A$5:$A$122,$A44,'Guide vs build'!$E$5:$E$122,"Missing") | F44: =IF(B44=0,0,C44/B44)
...

Sheet Line-by-line check
A1: Feature Guide — line-by-line check
A2: Every sentence, bullet and table row of the Feature Guide (28 Sep 2026), in order, against SeereonOS v6 (2 Oct 2026). Fill in 'Checked by Santosh' (Yes / No / Query) and 'Comments'.
A4: # | B4: Guide section | C4: Page | D4: Type | E4: Guide text (verbatim) | F4: G-ID(s) | G4: Where you see it in the build (menu › screen › section / column / button) | H4: Result | I4: Notes | J4: Checked by Santosh | K4: Comments
A5: 1 | B5: Introduction | C5: 1 | D5: Title | E5: Seereon Delivery Board: Feature Guide | F5: — | G5: Product is now SeereonOS; the guide's screens live in the left menu (Dashboard … Rules) | H5: OK — improved | I5: Renamed from Seereon Delivery Board to SeereonOS.
A6: 2 | B6: Introduction | C6: 1 | D6: Title | E6: Santosh Nayak · 28 Sep 2026 | F6: — | G6: — | H6: OK | I6: Guide author and date (reference only).
A7: 3 | B7: Introduction | C7: 1 | D7: Sentence | E7: This guide explains every feature of the board in plain words, one screen at a time, for the whole team: developers, the project manager, sales and new joiners. | F7: — | G7: Whole app | H7: OK | I7: Intro sentence; no feature.
A8: 4 | B8: Introduction | C8: 1 | D8: Sentence | E8: The screenshots come from the working prototype with dummy data. | F8: — | G8: Demo data in the build mirrors the prototype (Seereon tenant: EduReon, SeerHR, same people) | H8: OK
A9: 5 | B9: Introduction | C9: 1 | D9: Sentence | E9: The SaaS build keeps the same screens and rules; the Technical Design has the build detail. | F9: — | G9: Same screens and rules; build detail in specs/ (Technical Design) | H9: OK
A10: 6 | B10: 1. Roles and views | C10: 1 | D10: Heading | E10: 1. Roles and views | F10: G1.01–G1.06 | G10: Top bar + left menu + Dashboard (/home) | H10: OK
A11: 7 | B11: 1. Roles and views | C11: 1 | D11: Sentence | E11: Everyone uses the same board, but each person sees only what their role needs. | F11: G1.02, G1.05 | G11: One login; menu, buttons and data follow the person's permissions | H11: OK
A12: 8 | B12: 1. Roles and views | C12: 1 | D12: Sentence | E12: There are five roles: CEO (admin), project manager, sales, operations and employee. | F12: G1.02, G1.05 | G12: Admin › Organisation setup › Roles & permissions (/setup/roles): 9 default roles | H12: Intentional difference | I12: The five guide roles are kept as the five dashboard views; access comes from 9 configurable roles (Administrator, CEO, CTO, Project Manager, HR Manager, HR Executive, Sales Manager, Sales Executive, Employee).
A13: 9 | B13: 1. Roles and views | C13: 1 | D13: Screenshot caption | E13: Header with the week switcher, tabs, View as control and the five dashboard views | F13: G1.01–G1.04 | G13: Top bar (week switcher, View as) + left menu + Dashboard view switch | H13: OK | I13: Screenshot 000.
A14: 10 | B14: 1. Roles and views | C14: 1 | D14: Bullet | E14: Header: the company name, the week being viewed (use the arrows to move between weeks), and the tabs you are allowed to open. | F14: G1.01, G1.02 | G14: Top bar: company name, week switcher ‹ › with 'This week'; v7 grouped left menu shows only allowed items: Dashboard, My work › Timesheet & log, Projects & WBS (All projects, Milestones & billing, WBS, Schedule & critical path, Change requests, Resource allocation, Costing & margin, Client view, Import WBS), Tasks (All tasks, Timesheet approvals), Finance (Payroll, Ledger, Profit & loss, Profit margins), Company (Weekly scorecard, Insights, Operations, Rules), Admin › Team & settings | H14: OK — improved | I14: v6: menu names now match the guide's tabs. Week switcher also drives Tasks.
A15: 11 | B15: 1. Roles and views | C15: 1 | D15: Bullet | E15: View as (admin only): the CEO can switch to any role to check exactly what that person sees. | F15: G1.03 | G15: Top bar › View as (CEO / Administrator) | H15: Intentional difference | I15: View as offers the 9 configurable roles instead of 5 fixed ones.
A16: 12 | B16: 1. Roles and views | C16: 1 | D16: Bullet (cont.) | E16: In the SaaS version this mode is read-only, so nothing can be changed by accident. | F16: G1.03 | G16: Top bar › View as — banner 'Viewing as X — read-only'; every write refused | H16: OK
A17: 13 | B17: 1. Roles and views | C17: 1 | D17: Bullet | E17: Dashboard views: CEO, Project manager, Sales, Operations and Employee. | F17: G1.04 | G17: Dashboard (/home) — switch CEO · Project manager · Sales · Operations · Employee | H17: OK
A18: 14 | B18: 1. Roles and views | C18: 1 | D18: Bullet (cont.) | E18: A salesperson lands on Sales; an employee lands on Employee and cannot open the others. | F18: G1.04 | G18: Dashboard (/home): sales roles land on Sales; Employee lands on Employee with no switch | H18: OK
A19: 15 | B19: 1. Roles and views | C19: 1 | D19: Table row | E19: Role table — columns: Role | Lands on | Can change | Cannot see | F19: G1.05 | G19: Admin › Organisation setup › Roles & permissions (/setup/roles) | H19: OK | I19: Table header row.
A20: 16 | B20: 1. Roles and views | C20: 1 | D20: Table row | E20: CEO (admin) | CEO dashboard | Everything, including settings, rates and payroll | Nothing hidden | F20: G1.05 | G20: CEO role: all permissions; lands on Dashboard › CEO | H20: OK
A21: 17 | B21: 1. Roles and views | C21: 1 | D21: Table row | E21: Project manager | Project manager view | Own projects, tasks, allocation; approves team timesheets | Salaries, payroll, company finance (margins only if granted) | F21: G1.05 | G21: Project Manager role: own projects, tasks, allocation, approves team timesheets; no salaries / payroll / finance; margins only with the extra 'See project margins' grant | H21: OK | I21: v6: the PM demo user no longer has margins by default.
A22: 18 | B22: 1. Roles and views | C22: 1 | D22: Table row | E22: Sales | Sales view | Own leads and deals | Other people’s pay, project costs | F22: G1.05 | G22: Sales Manager / Sales Executive roles: own deals; Compensation shows own pay only; project costs refused | H22: OK
A23: 19 | B23: 1. Roles and views | C23: 1 | D23: Table row | E23: Operations | Operations view | Ops register, openings, leave entries | Salaries unless granted, margins | F23: G1.05 | G23: HR Manager / HR Executive roles: Operations, Openings, Leave › Record leave; margins refused | H23: Intentional difference | I23: HR Manager can also prepare payroll and see the ledger (CEO finalises via maker-checker).
A24: 20 | B24: 1. Roles and views | C24: 1 | D24: Table row | E24: Employee | Employee view | Own tasks’ status, own timesheet, comments | Other people’s timesheets, money | F24: G1.05 | G24: Employee role: own tasks' status, own timesheet, comments; no money, no other timesheets | H24: OK
A25: 21 | B25: 1. Roles and views | C25: 2 | D25: Screenshot caption | E25: Employee view: tasks tagged to me, my week at a glance | F25: G1.06 | G25: Dashboard › Employee (/home) | H25: OK | I25: Screenshot 001.
A26: 22 | B26: 1. Roles and views | C26: 2 | D26: Sentence | E26: The employee view shows only that person’s world: tasks where they were mentioned or tagged, tasks they are covering for a colleague on leave, and their own delivery numbers for the week. | F26: G1.06 | G26: Dashboard › Employee: 'Tagged you', 'Covering', week score, on-time, effort ratio, utilisation, overdue, average lateness | H26: OK | I26: Seed comments fixed in v6 (Tagged you shows the right EduReon task).
A27: 23 | B27: 2. CEO dashboard: revenue first | C27: 2 | D27: Heading | E27: 2. CEO dashboard: revenue first | F27: G2.01–G2.08 | G27: Dashboard › CEO › Overview (/home) | H27: OK
A28: 24 | B28: 2. CEO dashboard: revenue first | C28: 2 | D28: Sentence | E28: The CEO lands on revenue, because that is the number that decides everything else. | F28: G2.01 | G28: CEO lands on Dashboard › CEO › Overview, revenue cards first | H28: OK
A29: 25 | B29: 2. CEO dashboard: revenue first | C29: 2 | D29: Sentence | E29: The Overview shows this month, this quarter and this financial year (April to March) side by side. | F29: G2.02 | G29: Dashboard › CEO › Overview (/home) — 'Revenue and earnings': This month / This quarter / This financial year (Apr–Mar) | H29: OK
A30: 26 | B30: 2. CEO dashboard: revenue first | C30: 3 | D30: Screenshot caption | E30: Revenue and earnings: month, quarter and year, with the 12-month chart and revenue ahead | F30: G2.01–G2.05 | G30: Dashboard › CEO › Overview (/home) — 'Revenue and earnings', 'Monthly revenue, last 12 months', 'Revenue ahead' | H30: OK | I30: Screenshot 002.
A31: 27 | B31: 2. CEO dashboard: revenue first | C31: 3 | D31: Bullet | E31: Top four numbers: revenue this month, this quarter, this financial year, and net earnings for the year. | F31: G2.01 | G31: Dashboard › CEO › Overview (/home) — top four tiles: revenue month, quarter, FY, net earnings FY | H31: OK | I31: v6: month and quarter count only income up to today.
A32: 28 | B32: 2. CEO dashboard: revenue first | C32: 3 | D32: Bullet (cont.) | E32: The arrow shows the change against the previous period. | F32: G2.01 | G32: Dashboard › CEO › Overview (/home) — change arrow on each tile vs previous period | H32: OK
A33: 29 | B33: 2. CEO dashboard: revenue first | C33: 3 | D33: Bullet | E33: Period table: for each period, revenue billed, cash collected, total costs (salaries plus expenses), net earnings, net margin, and the change in revenue. | F33: G2.02 | G33: Dashboard › CEO › Overview (/home) — period table: Revenue billed, Collected, Costs, Net earnings, Net margin, Revenue change | H33: OK | I33: v6: costs use one salary basis, so the dashboard equals the P&L.
A34: 30 | B34: 2. CEO dashboard: revenue first | C34: 3 | D34: Bullet | E34: 12-month chart: billed and collected side by side, so a gap between invoicing and cash shows at a glance. | F34: G2.03 | G34: Dashboard › CEO › Overview (/home) — 'Monthly revenue, last 12 months' (billed vs collected, table toggle) | H34: OK | I34: No future months.
A35: 31 | B35: 2. CEO dashboard: revenue first | C35: 3 | D35: Bullet | E35: Where revenue came from: split by stream (SAP consulting, products, services, subscriptions, AMS). | F35: G2.04 | G35: Dashboard › CEO › Overview (/home) — 'Where revenue came from, this financial year': SAP consulting, Products, Services, Subscriptions, AMS | H35: OK | I35: v6: stream names now match the guide everywhere (dashboard, P&L).
A36: 32 | B36: 2. CEO dashboard: revenue first | C36: 3 | D36: Bullet | E36: Revenue ahead: milestones due but not yet invoiced, plus the weighted sales pipeline. | F36: G2.05 | G36: Dashboard › CEO › Overview (/home) — 'Revenue ahead': milestones billable 30/60/90 days + weighted pipeline | H36: OK
A37: 33 | B37: 2. CEO dashboard: revenue first | C37: 4 | D37: Screenshot caption | E37: Delivery and milestone cash: health of all projects and money due in 30 days | F37: G2.06, G2.07 | G37: Dashboard › CEO › Overview (/home) — 'Delivery' and 'Milestones and cash' | H37: OK | I37: Screenshot 003.
A38: 34 | B38: 2. CEO dashboard: revenue first | C38: 4 | D38: Sentence | E38: Below revenue, Delivery shows how many milestones were hit on time, the schedule performance index (SPI: above 1.0 means ahead of plan), average lateness and overdue tasks. | F38: G2.06 | G38: Dashboard › CEO › Overview (/home) — 'Delivery': Milestones hit on time, SPI, Average lateness, Overdue tasks (+ CPI, utilisation, projects in red, forecast to breach, done in 4 weeks, team score) | H38: OK — improved | I38: v6: added average lateness and overdue tasks as worded in the guide.
A39: 35 | B39: 2. CEO dashboard: revenue first | C39: 4 | D39: Sentence | E39: Milestones and cash lists milestones due in the next 30 days with their billing value, so the CEO sees which delivery dates carry money. | F39: G2.07 | G39: Dashboard › CEO › Overview (/home) — 'Milestones and cash': due in the next 30 days with deadline, forecast, status, billing | H39: OK
A40: 36 | B40: 3. Projects: list, status, type | C40: 4 | D40: Heading | E40: 3. Projects: list, status, type | F40: G3.01–G3.11 | G40: Projects & WBS › All projects (/projects) | H40: OK | I40: Menu group 'Projects & WBS' as in the guide (v7: project areas also reachable as submenus).
A41: 37 | B41: 3. Projects: list, status, type | C41: 4 | D41: Sentence | E41: The Projects tab opens on a list of all projects. | F41: G3.01 | G41: Projects & WBS › All projects (/projects) — list of all projects the person may see | H41: OK
...

Sheet Guide vs build
A1: Feature Guide vs SeereonOS build
A2: One row per Feature Guide item (checklist G1.01–G17.02). Fill in 'Checked by Santosh' (Yes / No / Query) and 'Comments' — the only columns to edit.
A4: Guide section | B4: ID | C4: Guide feature (checklist wording) | D4: Guide page / screenshot reference | E4: In build? | F4: Where in the build (screen / route) | G4: API endpoint | H4: Notes / improvements | I4: Checked by Santosh | J4: Comments
A5: 1. Roles and views | B5: G1.01 | C5: Header: company name, week switcher (prev/next week arrows, "This week" label) that drives the week shown on dashboards/timesheet/scorecard | D5: §1 Roles and views · p.1 · screenshot 000 | E5: Present | F5: Top bar (every page) + left menu — Top bar: company name, week switcher ‹ 28 Sept – 2 Oct › with 'This week'; drives Dashboard, Tasks, Timesheet & log, Weekly scorecard, Pipeline. Menu names now match the guide tabs: Dashboard, Projects & WBS, Tasks, Timesheet & log, Weekly scorecard, Insights, Client view, Team & settings, Rules | G5: ?week= on GET /dashboards/ceo, /dashboards/pm, /dashboards/employee, /scorecard, /timesheets/:week, /sales/summary | H5: v6: menu renamed to the guide's tab names.
A6: 1. Roles and views | B6: G1.02 | C6: Tabs visible per role | D6: §1 Roles and views · p.1 · screenshot 000 | E6: Present | F6: Left menu (v7 groups with submenus), More sheet, phone tab bar — Left menu, More sheet and phone tab bar filtered by permission, using the guide's tab names; every route guarded | G6: GET /me (permissions) | H6: Roles are configurable permissions (9 default roles).
A7: 1. Roles and views | B7: G1.03 | C7: View as (admin): switch to any role, read-only | D7: §1 Roles and views · p.1 · screenshot 000 | E7: Present | F7: Top bar › View as — View as (top bar and More sheet) lists the 9 configurable roles; banner 'Viewing as X — read-only' | G7: GET /roles; X-View-As header; writes refused 403 VIEW_AS_READ_ONLY | H7: Intentional difference: View as offers the 9 configurable roles (guide had 5 fixed roles); read-only as the guide says.
A8: 1. Roles and views | B8: G1.04 | C8: Five dashboard views CEO / PM / Sales / Operations / Employee; each role lands on its own; employee cannot open others; CEO can switch between the 5 dashboards (segmented switch) and CEO dashboard has sub-tabs Overview / Projects / Sales / Finance / Operations | D8: §1 Roles and views · p.1 · screenshot 000 | E8: Present | F8: Dashboard (/home) — Home /home: each person lands on own view; switch CEO · Project manager · Sales · Operations · Employee for people allowed several; CEO sub-tabs Overview / Projects / Sales / Finance / Operations | G8: GET /dashboards/ceo|pm|sales|ops|employee (403 without permission) |
A9: 1. Roles and views | B9: G1.05 | C9: Role matrix: PM sees own projects, tasks, allocation, approves team timesheets, no salaries/payroll/finance (margins only if granted); Sales own leads; Ops register, openings, leave entries; Employee own tasks' status, own timesheet, comments | D9: §1 Roles and views · p.1 · text only (no screenshot) | E9: Present | F9: Admin › Organisation setup › Roles & permissions (/setup/roles) — Default roles: Project Manager = own projects, tasks, allocation, approves team timesheets, no salaries/payroll/finance, margins only with an extra grant; Sales own deals; HR Manager / HR Executive = ops register, openings, leave entries; Employee self-service | G9: permission catalogue; server scoping | H9: Intentional difference: HR Manager can prepare payroll and see the ledger (CEO finalises via maker-checker). Project Manager sees own projects only.
A10: 1. Roles and views | B10: G1.06 | C10: Employee view: person picker (for CEO/PM), "Tagged you" list (mention comments with Open task), "Covering" tasks for colleagues on leave, own numbers: this week's score, on-time delivery, effort ratio, utilisation next 10 working days, + more (open tasks, avg lateness, overdue, etc.) | D10: §1 Roles and views · p.2 · screenshot 001 | E10: Present | F10: Dashboard › Employee (/home) — Employee view (Home → Employee): person picker for CEO/PM; "Tagged you" with Open task; "Covering"; week score, on-time, effort ratio, utilisation next 10 days, open, overdue, average lateness, forecast to breach | G10: GET /dashboards/employee?user=&week=; GET /tasks/mentions |
A11: 2. CEO dashboard: revenue first | B11: G2.01 | C11: Top 4: revenue this month, quarter, FY (Apr–Mar), net earnings FY, each with change arrow vs previous period | D11: §2 CEO dashboard: revenue first · p.3 · screenshot 002 | E11: Present | F11: Dashboard › CEO › Overview (/home) — CEO Overview "Revenue and earnings": revenue month / quarter / FY and net earnings FY, each with change arrow | G11: GET /dashboards/ceo | | H11: v6: month and quarter count only income to date.
A12: 2. CEO dashboard: revenue first | B12: G2.02 | C12: Period table: billed, collected, costs (salaries + expenses), net earnings, net margin, revenue change for month/quarter/FY | D12: §2 CEO dashboard: revenue first · p.3 · screenshot 002 | E12: Present | F12: Dashboard › CEO › Overview (/home) — CEO Overview fixed table This month / This quarter / This FY: billed, collected, costs (salaries + expenses), net earnings, net margin, revenue change | G12: GET /dashboards/ceo | H12: v6: one salary basis, so the dashboard and the P&L agree.
A13: 2. CEO dashboard: revenue first | B13: G2.03 | C13: 12-month chart billed vs collected | D13: §2 CEO dashboard: revenue first · p.3 · screenshot 002 | E13: Present | F13: Dashboard › CEO › Overview (/home) — "Monthly revenue, last 12 months" billed vs collected chart (+ table toggle, export) | G13: GET /dashboards/ceo |
A14: 2. CEO dashboard: revenue first | B14: G2.04 | C14: Revenue by stream (SAP consulting, project milestones/products, services, subscriptions/AMC, AMS) with % share | D14: §2 CEO dashboard: revenue first · p.3 · screenshot 002 | E14: Present | F14: Dashboard › CEO › Overview (/home) — 'Where revenue came from, this financial year': SAP consulting, Products, Services, Subscriptions, AMS with ₹ and % (same names on the P&L) | G14: GET /dashboards/ceo | | H14: v6: stream names match the guide.
A15: 2. CEO dashboard: revenue first | B15: G2.05 | C15: Revenue ahead: milestones billable in 30/60/90 days + weighted sales pipeline | D15: §2 CEO dashboard: revenue first · p.3 · screenshot 002 | E15: Present | F15: Dashboard › CEO › Overview (/home) — "Revenue ahead": milestones billable in 30 / 60 / 90 days + weighted sales pipeline | G15: GET /dashboards/ceo |
A16: 2. CEO dashboard: revenue first | B16: G2.06 | C16: Delivery KPIs: on-time delivery, avg SPI, avg CPI, utilisation next 10 days, active projects in red, open tasks already breached, tasks forecast to breach, tasks done last 4 weeks (vs previous 4), team weekly score | D16: §2 CEO dashboard: revenue first · p.4 · screenshot 003 | E16: Present | F16: Dashboard › CEO › Overview (/home) — 'Delivery': milestones hit on time, SPI, average lateness, overdue tasks, plus CPI, utilisation next 10 days, projects in red, forecast to breach, done last 4 weeks, team weekly score | G16: GET /dashboards/ceo | | H16: v6: added average lateness and overdue tasks.
A17: 2. CEO dashboard: revenue first | B17: G2.07 | C17: Milestones and cash: milestones achieved on time %, achieved-not-invoiced ₹, invoiced-awaiting-payment ₹, billable next 30 days; table of milestones due in 30 days with deadline, forecast, status, billing | D17: §2 CEO dashboard: revenue first · p.4 · screenshot 003 | E17: Present | F17: Dashboard › CEO › Overview (/home) — "Milestones and cash": milestones on time %, achieved not invoiced ₹, invoiced awaiting payment ₹, billable next 30 days; table due in 30 days with deadline, forecast (red when late), status, billing | G17: GET /dashboards/ceo |
A18: 2. CEO dashboard: revenue first | B18: G2.08 | C18: Footnote definitions of revenue / costs / net earnings | D18: §2 CEO dashboard: revenue first · p.3 · screenshot 002 | E18: Present | F18: Dashboard › CEO › Overview (/home) — Footnote defining revenue, costs, net earnings (also in exports) | G18: — |
A19: 3. Projects: list, status, type | B19: G3.01 | C19: Status chips All/Initiated/Active/On hold/NPA/Completed/Closed with counts, filter | D19: §3 Projects: list, status, type · p.4 · screenshot 004 | E19: Present | F19: Projects & WBS › All projects (/projects) — Projects /projects: status chips All / Initiated / Active / On hold / NPA / Completed / Closed with counts | G19: GET /projects |
A20: 3. Projects: list, status, type | B20: G3.02 | C20: Status/health column: health badge (On track/At risk/Off track) + inline status dropdown | D20: §3 Projects: list, status, type · p.4 · screenshot 004 | E20: Present | F20: Projects & WBS › All projects (/projects) — Status column: health badge + inline status dropdown; 'What the statuses mean' popover next to the chips and meanings in the dropdown and reason dialog | G20: POST /projects/:id/status | | H20: v6: status meanings popover added.
A21: 3. Projects: list, status, type | B21: G3.03 | C21: Moving to On hold / NPA / Closed requires reason; status history kept | D21: §3 Projects: list, status, type · p.4 · screenshot 004 | E21: Present | F21: Projects & WBS › All projects (/projects) — Reason required for On hold / NPA / Closed; status history in project Activity tab | G21: POST /projects/:id/status (422 if no reason); GET /projects/:id/activity |
A22: 3. Projects: list, status, type | B22: G3.04 | C22: Columns: PM, commercial model (Fixed / T&M), type, progress (% and x/y tasks), planned end, forecast end (red when late, "+Nd late"/"Nd early"), next milestone (Mx date name), contract value, projected margin | D22: §3 Projects: list, status, type · p.4 · screenshot 004 | E22: Present | F22: Projects & WBS › All projects (/projects) — Columns PM, model ('Fixed price' / 'Time & material') + type, progress, planned end, forecast end, next milestone, contract, projected margin — all fit at 1280 px+ without scrolling | G22: GET /projects (row) | | H22: v6: columns fit without scrolling; 'Fixed price' everywhere.
A23: 3. Projects: list, status, type | B23: G3.05 | C23: Expand row inline (click again to close) | D23: §3 Projects: list, status, type · p.4 · screenshot 004 | E23: Present | F23: Projects & WBS › All projects (/projects) — Row expands inline (click again closes): milestones, PM, dates, open tasks, critical risks, Open project / Client view | G23: GET /projects/:id/summary |
A24: 3. Projects: list, status, type | B24: G3.06 | C24: Project types Product / Service / SaaS / AMS | D24: §3 Projects: list, status, type · p.4 · screenshot 004 | E24: Present | F24: Projects & WBS › All projects (/projects) — Types Product / Service / SaaS / AMS | G24: POST /projects |
A25: 3. Projects: list, status, type | B25: G3.07 | C25: Create project form: name, client, PM, start, planned end, working-days/weekends/holidays summary for the date range, type, commercial model, priority (1..n with labels), auto project code | D25: §3 Projects: list, status, type · p.6 · screenshot 005 | E25: Present | F25: Projects & WBS › Create project (/projects/new) — Create project: name, client, PM, start, planned end, calendar line (calendar days, weekends, holidays named, working days), type, commercial model, priority 1–5 with labels, auto code shown | G25: GET /projects/next-code; POST /projects/costing/preview; POST /projects |
A26: 3. Projects: list, status, type | B26: G3.08 | C26: AUTO MILESTONE SETUP in create form: milestones one per line "name | billing amount" → M1..Mn created in order with billing amounts | D26: §3 Projects: list, status, type · p.6 · screenshot 005 | E26: Present | F26: Projects & WBS › Create project (/projects/new) — AUTO MILESTONE SETUP: "one per line, name | G26: amount" textarea → live M1..Mn preview (bad amounts / duplicates flagged, 3L / 75K shorthand) or "Edit as rows"; deadlines auto-spread over working days until tasks exist | H26: POST /projects (milestones[]) |
A27: 3. Projects: list, status, type | B27: G3.09 | C27: Documents upload in create form (PDF, images, text, CSV up to 20 MB each) | D27: §3 Projects: list, status, type · p.6 · screenshot 005 | E27: Present | F27: Projects & WBS › Create project (/projects/new) — Documents in create form: PDF, images, text, CSV, 20 MB each, multiple → project Documents | G27: POST /projects (documents[]) |
A28: 3. Projects: list, status, type | B28: G3.10 | C28: PROJECT COST CALCULATOR in create form (editors only): Resources rows (resource, milestone or All, alloc %, from*, to* default to milestone dates, working days, man-days, cost/day, cost, remove), same person multiple rows; Additional costs (category, description, amount); Maintenance/support cost; Contingency % of resources+additional; Markup %; Project price (computed both ways); planned margin; totals | D28: §3 Projects: list, status, type · p.6 · screenshot 005 | E28: Present | F28: Projects & WBS › Create project (/projects/new); Projects & WBS › All projects › project › Costing & margin (/projects/:id/costing); direct: Projects & WBS › Costing & margin — Project cost calculator in the create form and on the Costing & margin tab: resources (person, milestone, %, from/to, working days, hours, cost/day, cost), additional costs, maintenance, contingency %, markup ⇄ price, totals and planned margin; cost per hour = CTC ÷ (working days in the month × minimum hours) | G28: POST /projects/costing/preview; POST /projects; PUT /projects/:id/costing | | H28: v6: cost loading removed.
A29: 3. Projects: list, status, type | B29: G3.11 | C29: Cost per day = CTC ÷ average working days per month × (1 + cost loading %); cost loading set in Finance | D29: §3 Projects: list, status, type · p.6 · screenshot 005 | E29: Present | F29: Projects & WBS › Create project (/projects/new) (Project cost calculator); Admin › Team & settings › Cost rates (/settings/cost-rates) — Cost per day = minimum hours × cost per hour, where cost per hour = CTC ÷ (working days in the month × minimum hours); shown in the calculator and on Cost rates | G29: GET /costing/rates; POST /projects/costing/preview | H29: v6: formula changed to the guide's cost per hour; cost loading removed.
A30: 4. Project page: milestones, tasks and WBS | B30: G4.01 | C30: Milestones numbered M1.. in creation order; tasks 2.1, 2.2; numbers never change / never reused | D30: §4 Project page: milestones, tasks and WBS · p.7 · screenshot 006 | E30: Present | F30: Projects & WBS › All projects › project › WBS (/projects/:id/wbs); direct: Projects & WBS › Milestones & billing / WBS — M1.. and 1.1, 1.2 numbering from sequences; a task keeps its number when its milestone is deleted or it moves (4.1 stays 4.1 under 'No milestone') | G30: POST /projects/:id/milestones; POST /projects/:id/tasks | | H30: v6: task numbers survive milestone deletion.
A31: 4. Project page: milestones, tasks and WBS | B31: G4.02 | C31: Milestone deadline = target end of its last task (auto); baseline date shown; slip shown in red (+5d) | D31: §4 Project page: milestones, tasks and WBS · p.7 · screenshot 006 | E31: Present | F31: Projects & WBS › All projects › project › WBS (/projects/:id/wbs); direct: Projects & WBS › Milestones & billing / WBS — Milestone deadline = target end of its last task (automatic), baseline under it, red slip "+Nd"; provisional until tasks exist | G31: syncMilestoneDates; PATCH /milestones/:id refuses manual dates once tasks exist |
A32: 4. Project page: milestones, tasks and WBS | B32: G4.03 | C32: Milestone status: Achieved on time / Achieved late / On track / At risk; End column (actual achieved or forecast) | D32: §4 Project page: milestones, tasks and WBS · p.7 · screenshot 006 | E32: Present | F32: Projects & WBS › All projects › project › WBS (/projects/:id/wbs); direct: Projects & WBS › Milestones & billing / WBS — Milestones table: Status (Achieved on time / Achieved late / On track / At risk, + Overdue / Not started) and End (achieved or forecast) | G32: GET /projects/:id |
A33: 4. Project page: milestones, tasks and WBS | B33: G4.04 | C33: Milestone progress bar %, task count | D33: §4 Project page: milestones, tasks and WBS · p.7 · screenshot 006 | E33: Present | F33: Projects & WBS › All projects › project › WBS (/projects/:id/wbs); direct: Projects & WBS › Milestones & billing / WBS — Progress bar % + N tasks | G33: GET /projects/:id |
A34: 4. Project page: milestones, tasks and WBS | B34: G4.05 | C34: Billing per milestone: amount + state dropdown (Not due / Invoiced / Paid); summary line paid / invoiced-unpaid / achieved-not-invoiced of total | D34: §4 Project page: milestones, tasks and WBS · p.7 · screenshot 006 | E34: Present | F34: Projects & WBS › All projects › project › WBS (/projects/:id/wbs); direct: Projects & WBS › Milestones & billing / WBS — Billing amount + Not due / Invoiced / Paid dropdown (raises invoice / records payment); summary "paid / invoiced and unpaid / achieved not invoiced of total" | G34: POST /milestones/:id/invoice; POST /invoices/:id/payments |
A35: 4. Project page: milestones, tasks and WBS | B35: G4.06 | C35: Edit milestone (name, dates, amount); Delete blocked if invoiced; deleting moves tasks to "No milestone" | D35: §4 Project page: milestones, tasks and WBS · p.7 · screenshot 006 | E35: Present | F35: Projects & WBS › All projects › project › WBS (/projects/:id/wbs); direct: Projects & WBS › Milestones & billing / WBS — Edit (name, amount; dates locked once tasks exist), Delete blocked when invoiced, tasks move to "No milestone" | G35: PATCH / DELETE /milestones/:id | | H35: Dates follow the last task once a milestone has tasks (editable while it has none).
A36: 4. Project page: milestones, tasks and WBS | B36: G4.07 | C36: Auto-cleanup: milestone with no tasks for 7 days removed automatically unless invoiced | D36: §4 Project page: milestones, tasks and WBS · p.7 · screenshot 006 | E36: Present | F36: Projects & WBS › All projects › project › WBS (/projects/:id/wbs); direct: Projects & WBS › Milestones & billing / WBS — Auto-cleanup of milestones with no tasks for 7 days unless invoiced ("no tasks: removed {date}") | G36: sweepMilestones on project, list and dashboard reads; setting projects.empty_milestone_days |
A37: 4. Project page: milestones, tasks and WBS | B37: G4.08 | C37: Add milestone inline: name + optional billing amount | D37: §4 Project page: milestones, tasks and WBS · p.7 · screenshot 006 | E37: Present | F37: Projects & WBS › All projects › project › WBS (/projects/:id/wbs); direct: Projects & WBS › Milestones & billing / WBS — Inline add: name + optional billing amount, no dates needed | G37: POST /projects/:id/milestones |
A38: 4. Project page: milestones, tasks and WBS | B38: G4.09 | C38: WBS table: milestone rows with rollups (done %, effort est/actual, start, target end, end) and +Task per milestone; task rows: number, title, "after x.y" dependencies, owner, done %, effort est/actual, start plan/actual, target end (with revisions), end actual/forecast (green/red), float to milestone; critical tasks marked | D38: §4 Project page: milestones, tasks and WBS · p.8 · screenshot 007 | E38: Present | F38: Projects & WBS › All projects › project › WBS (/projects/:id/wbs); direct: Projects & WBS › Milestones & billing / WBS — WBS table: milestone rollups + '+ Task'; task rows WBS no., title, 'after x.y', owner, stage, done %, effort est/actual, start plan/actual, target end (rev), end actual/forecast, float to milestone with 'project: Nd' (float to project end) underneath; critical rows red | G38: GET /projects/:id | | H38: v6: float cell shows float to milestone plus 'project: Nd' (working days before the project end slips, as the guide defines float).
A39: 4. Project page: milestones, tasks and WBS | B39: G4.10 | C39: WBS import: paste rows or upload CSV (Milestone, Task, Owner, Estimated hours, Start, End, Complexity, Depends on, Milestone billing); template download; preview with row errors (unknown owner, bad date, unknown dependency); all-or-nothing save | D39: §4 Project page: milestones, tasks and WBS · p.6 · text only (no screenshot) | E39: Present | F39: Projects & WBS › Import WBS (/delivery/import); project › Import WBS (/projects/:id/import) — WBS import: paste / CSV, template download, preview with row errors, all-or-nothing | G39: POST /projects/:id/import?mode=preview|commit |
A40: 5. Schedule, critical path and change requests | B40: G5.01 | C40: Gantt: bar per task grouped by milestone, planned vs actual/forecast bars, critical in red, milestone deadline and forecast diamonds, today line, baseline | D40: §5 Schedule, critical path and change requests · p.9 · screenshot 008 | E40: Present | F40: Projects & WBS › All projects › project › Schedule (/projects/:id/schedule); direct: Projects & WBS › Schedule & critical path — Schedule tab Gantt: bars by milestone, planned vs actual/forecast, critical red, deadline & forecast diamonds, today line, baselines, zoom; scrolls inside its card on phones | G40: GET /projects/:id/schedule |
A41: 5. Schedule, critical path and change requests | B41: G5.02 | C41: Critical path text summary (chain with dates, end date) | D41: §5 Schedule, critical path and change requests · p.9 · screenshot 008 | E41: Present | F41: Projects & WBS › All projects › project › Schedule (/projects/:id/schedule); direct: Projects & WBS › Schedule & critical path — "Critical path: 1.1 (dates) › 1.2 … Ends {date}" | G41: GET /projects/:id/schedule |
...

Sheet Build feature list
A1: SeereonOS build — complete feature list
A2: Every live feature in the build. Source = Feature Guide (with G-ID) or Additional (layer it came from). Planned catalogue processes are not listed. Default roles: Administrator, CEO, CTO, Project Manager, HR Manager, HR Executive, Sales Manager, Sales Executive, Employee.
A4: # | B4: Area | C4: Feature | D4: Screen / route | E4: Who can use it (default roles) | F4: Source | G4: Process catalogue IDs | H4: Status
A5: 1 | B5: Dashboards | C5: Five role dashboards with CEO switch and sub-tabs | D5: Dashboard (/home) | E5: Everyone (own data) | F5: Feature Guide (G1.04) | G5: ANA-01, ANA-03 | H5: Live
A6: 2 | B6: Dashboards | C6: Employee view: Tagged you, Covering, own numbers | D6: Dashboard › Employee (/home) | E6: Everyone (own data) | F6: Feature Guide (G1.06) | G6: ANA-05 | H6: Live
A7: 3 | B7: Dashboards | C7: Top 4 revenue and net earnings tiles | D7: Dashboard › CEO › Overview (/home) | E7: Administrator, CEO | F7: Feature Guide (G2.01) | H7: Live
A8: 4 | B8: Dashboards | C8: Period table: billed, collected, costs, net, margin | D8: Dashboard › CEO › Overview (/home) | E8: Administrator, CEO | F8: Feature Guide (G2.02) | H8: Live
A9: 5 | B9: Dashboards | C9: 12-month billed vs collected chart | D9: Dashboard › CEO › Overview (/home) | E9: Administrator, CEO | F9: Feature Guide (G2.03) | H9: Live
A10: 6 | B10: Dashboards | C10: Revenue by stream with % share | D10: Dashboard › CEO › Overview (/home) | E10: Administrator, CEO | F10: Feature Guide (G2.04) | H10: Live
A11: 7 | B11: Dashboards | C11: Revenue ahead (30/60/90 days + weighted pipeline) | D11: Dashboard › CEO › Overview (/home) | E11: Administrator, CEO | F11: Feature Guide (G2.05) | H11: Live
A12: 8 | B12: Dashboards | C12: Delivery KPIs (on-time, SPI, CPI, utilisation…) | D12: Dashboard › CEO › Overview (/home) | E12: Administrator, CEO | F12: Feature Guide (G2.06) | H12: Live
A13: 9 | B13: Dashboards | C13: Milestones and cash | D13: Dashboard › CEO › Overview (/home) | E13: Administrator, CEO | F13: Feature Guide (G2.07) | H13: Live
A14: 10 | B14: Dashboards | C14: Footnote definitions of revenue, costs, net earnings | D14: Dashboard › CEO › Overview (/home) | E14: Administrator, CEO | F14: Feature Guide (G2.08) | H14: Live
A15: 11 | B15: Dashboards | C15: PM delivery control KPIs | D15: Dashboard › Project manager (/home) | E15: Administrator, CEO, CTO, Project Manager | F15: Feature Guide (G14.01) | G15: ANA-02 | H15: Live
A16: 12 | B16: Dashboards | C16: Task pipeline chart | D16: Dashboard › Project manager (/home) | E16: Administrator, CEO, CTO, Project Manager | F16: Feature Guide (G14.02) | H16: Live
A17: 13 | B17: Dashboards | C17: Resource load next 10 working days | D17: Dashboard › Project manager (/home) | E17: Administrator, CEO, CTO, Project Manager | F17: Feature Guide (G14.03) | H17: Live
A18: 14 | B18: Dashboards | C18: HR & operations home: on leave today, compliance calendar (60 days), openings, payroll | D18: /home → Operations | E18: Administrator, CEO, HR Manager, HR Executive | F18: Additional (v1 base) | G18: ANA-04 | H18: Live
A19: 15 | B19: Dashboards | C19: Persona-based home: CTO, HR and other default roles land on the right dashboard | D19: /home | E19: Everyone (own data) | F19: Additional (v4 access & controls) | G19: ACC-09 | H19: Live
A20: 16 | B20: Projects & delivery | C20: Project status chips with counts | D20: Projects & WBS › All projects (/projects) | E20: All roles (own projects); full: Administrator, CEO, CTO, HR Manager | F20: Feature Guide (G3.01) | H20: Live
A21: 17 | B21: Projects & delivery | C21: Health badge and inline status dropdown | D21: Projects & WBS › All projects (/projects) | E21: Administrator, CEO, CTO, Project Manager | F21: Feature Guide (G3.02) | H21: Live
A22: 18 | B22: Projects & delivery | C22: Reason required for On hold / NPA / Closed; status history | D22: Projects & WBS › All projects (/projects) | E22: Administrator, CEO, CTO, Project Manager | F22: Feature Guide (G3.03) | G22: DEL-07, DEL-11 | H22: Live
A23: 19 | B23: Projects & delivery | C23: Projects list columns (PM, model, progress, forecast, margin…) | D23: Projects & WBS › All projects (/projects) | E23: All roles (own projects); full: Administrator, CEO, CTO, HR Manager | F23: Feature Guide (G3.04) | H23: Live
A24: 20 | B24: Projects & delivery | C24: Inline row expand | D24: Projects & WBS › All projects (/projects) | E24: All roles (own projects); full: Administrator, CEO, CTO, HR Manager | F24: Feature Guide (G3.05) | H24: Live
A25: 21 | B25: Projects & delivery | C25: Project types Product / Service / SaaS / AMS | D25: Projects & WBS › All projects (/projects) | E25: Administrator, CEO, CTO, Project Manager | F25: Feature Guide (G3.06) | H25: Live
A26: 22 | B26: Projects & delivery | C26: Create project form with calendar summary and auto code | D26: Projects & WBS › Create project (/projects/new) | E26: Administrator, CEO, CTO, Project Manager | F26: Feature Guide (G3.07) | G26: DEL-01 | H26: Live
A27: 23 | B27: Projects & delivery | C27: Auto milestone setup (name | amount per line) | D27: Projects & WBS › Create project (/projects/new) | E27: Administrator, CEO, CTO, Project Manager | F27: Feature Guide (G3.08) | H27: Live
A28: 24 | B28: Projects & delivery | C28: Documents upload in create form | D28: Projects & WBS › Create project (/projects/new) | E28: Administrator, CEO, CTO, Project Manager | F28: Feature Guide (G3.09) | H28: Live
A29: 25 | B29: Projects & delivery | C29: Project cost calculator | D29: Projects & WBS › Create project (/projects/new); Projects & WBS › All projects › project › Costing & margin (/projects/:id/costing); direct: Projects & WBS › Costing & margin | E29: Administrator, CEO, CTO, Project Manager | F29: Feature Guide (G3.10) | H29: Live
A30: 26 | B30: Projects & delivery | C30: Cost per day from cost per hour | D30: Projects & WBS › Create project (/projects/new) (Project cost calculator); Admin › Team & settings › Cost rates (/settings/cost-rates) | E30: Administrator, CEO | F30: Feature Guide (G3.11) | H30: Live
A31: 27 | B31: Projects & delivery | C31: Permanent milestone and task numbering | D31: Projects & WBS › All projects › project › WBS (/projects/:id/wbs); direct: Projects & WBS › Milestones & billing / WBS | E31: Edit: Administrator, CEO, CTO, Project Manager; view: project team | F31: Feature Guide (G4.01) | H31: Live
A32: 28 | B32: Projects & delivery | C32: Milestone deadline from last task, baseline and slip | D32: Projects & WBS › All projects › project › WBS (/projects/:id/wbs); direct: Projects & WBS › Milestones & billing / WBS | E32: Edit: Administrator, CEO, CTO, Project Manager; view: project team | F32: Feature Guide (G4.02) | G32: DEL-02 | H32: Live
A33: 29 | B33: Projects & delivery | C33: Milestone status and End column | D33: Projects & WBS › All projects › project › WBS (/projects/:id/wbs); direct: Projects & WBS › Milestones & billing / WBS | E33: Edit: Administrator, CEO, CTO, Project Manager; view: project team | F33: Feature Guide (G4.03) | H33: Live
A34: 30 | B34: Projects & delivery | C34: Milestone progress bar and task count | D34: Projects & WBS › All projects › project › WBS (/projects/:id/wbs); direct: Projects & WBS › Milestones & billing / WBS | E34: Edit: Administrator, CEO, CTO, Project Manager; view: project team | F34: Feature Guide (G4.04) | H34: Live
A35: 31 | B35: Projects & delivery | C35: Milestone billing state and billing summary | D35: Projects & WBS › All projects › project › WBS (/projects/:id/wbs); direct: Projects & WBS › Milestones & billing / WBS | E35: Edit: Administrator, CEO, CTO, Project Manager; view: project team | F35: Feature Guide (G4.05) | G35: FIN-01 | H35: Live
A36: 32 | B36: Projects & delivery | C36: Edit / delete milestone (blocked if invoiced) | D36: Projects & WBS › All projects › project › WBS (/projects/:id/wbs); direct: Projects & WBS › Milestones & billing / WBS | E36: Edit: Administrator, CEO, CTO, Project Manager; view: project team | F36: Feature Guide (G4.06) | H36: Live
A37: 33 | B37: Projects & delivery | C37: Auto-cleanup of empty milestones after 7 days | D37: Projects & WBS › All projects › project › WBS (/projects/:id/wbs); direct: Projects & WBS › Milestones & billing / WBS | E37: Edit: Administrator, CEO, CTO, Project Manager; view: project team | F37: Feature Guide (G4.07) | H37: Live
A38: 34 | B38: Projects & delivery | C38: Inline add milestone | D38: Projects & WBS › All projects › project › WBS (/projects/:id/wbs); direct: Projects & WBS › Milestones & billing / WBS | E38: Edit: Administrator, CEO, CTO, Project Manager; view: project team | F38: Feature Guide (G4.08) | H38: Live
A39: 35 | B39: Projects & delivery | C39: WBS table with rollups, dependencies, float, critical rows | D39: Projects & WBS › All projects › project › WBS (/projects/:id/wbs); direct: Projects & WBS › Milestones & billing / WBS | E39: Edit: Administrator, CEO, CTO, Project Manager; view: project team | F39: Feature Guide (G4.09) | G39: DEL-03 | H39: Live
A40: 36 | B40: Projects & delivery | C40: WBS import (paste / CSV) with preview | D40: Projects & WBS › Import WBS (/delivery/import); project › Import WBS (/projects/:id/import) | E40: Edit: Administrator, CEO, CTO, Project Manager; view: project team | F40: Feature Guide (G4.10) | G40: DEL-04 | H40: Live
A41: 37 | B41: Projects & delivery | C41: Gantt chart | D41: Projects & WBS › All projects › project › Schedule (/projects/:id/schedule); direct: Projects & WBS › Schedule & critical path | E41: All roles (project team); full: Administrator, CEO, CTO, HR Manager | F41: Feature Guide (G5.01) | G41: DEL-06 | H41: Live
...

Sheet Additional features
A1: Built in addition to the Feature Guide
A2: Features in SeereonOS that the Feature Guide does not ask for (same rows as 'Additional' on the Build feature list).
A4: # | B4: Area | C4: Feature | D4: Screen / route | E4: Who can use it (default roles) | F4: Added in | G4: Process catalogue IDs | H4: Why it helps
A5: 1 | B5: Dashboards | C5: HR & operations home: on leave today, compliance calendar (60 days), openings, payroll | D5: /home → Operations | E5: Administrator, CEO, HR Manager, HR Executive | F5: v1 base | G5: ANA-04 | H5: HR sees today's people picture and upcoming statutory dates.
A6: 2 | B6: Dashboards | C6: Persona-based home: CTO, HR and other default roles land on the right dashboard | D6: /home | E6: Everyone (own data) | F6: v4 access & controls | G6: ACC-09 | H6: Every role opens to the dashboard that fits its job.
A7: 3 | B7: Projects & delivery | C7: Project Overview and Activity tabs (status history and audit per project) | D7: /projects/:id; /projects/:id/activity | E7: All roles (project team); full: Administrator, CEO, CTO, HR Manager | F7: v1 base | G7: DEL-07 | H7: Full project history in one place.
A8: 4 | B8: Projects & delivery | C8: Hand a project over to another project manager | D8: /projects/:id | E8: Administrator, CEO, CTO | F8: v4 access & controls | H8: Leadership can reassign projects cleanly.
A9: 5 | B9: Projects & delivery | C9: Margin-floor warning in the project cost calculator | D9: /projects → New project; /projects/:id/money | E9: Administrator, CEO, CTO, Project Manager | F9: v5 parity extras | H9: Stops under-priced projects before they are signed.
A10: 6 | B10: Projects & delivery | C10: Milestone billing shorthand (3L / 75K) and 'Edit as rows' in auto milestone setup | D10: /projects → New project | E10: Administrator, CEO, CTO, Project Manager | F10: v5 parity extras | H10: Faster project set-up with fewer typing errors.
A11: 7 | B11: Projects & delivery | C11: Gantt zoom levels | D11: /projects/:id/schedule | E11: All roles (project team); full: Administrator, CEO, CTO, HR Manager | F11: v5 parity extras | H11: Read long projects by week or month.
A12: 8 | B12: Projects & delivery | C12: Staffing openings | D12: /openings | E12: Administrator, CEO, CTO, Project Manager, HR Manager, HR Executive | F12: v1 base | G12: HR-01 | H12: Links hiring needs to projects.
A13: 9 | B13: Projects & delivery | C13: Project areas without opening a project: Milestones & billing, WBS, Schedule, Change requests, Resource allocation, Costing & margin, Project documents, Client view, Import WBS | D13: /delivery/* | E13: Everyone (own data) | F13: v7 workflows, documents & invoicing | H13: Cross-project overviews plus a project picker that shows the same project tabs.
A14: 10 | B14: Projects & delivery | C14: Standalone project cost calculator for prospective projects (saved estimates, roles with assumed CTC, scenarios, compare) | D14: /projects/cost-calculator | E14: Administrator, CEO, CTO, Project Manager, Sales Manager | F14: v7 workflows, documents & invoicing | H14: Price and margin can be worked out before a deal is won.
A15: 11 | B15: Projects & delivery | C15: Estimate PDFs (internal costing, client quote) and Convert to project | D15: /projects/cost-calculator/:id | E15: Administrator, CEO, CTO, Project Manager, Sales Manager | F15: v7 workflows, documents & invoicing | H15: A won estimate becomes a project with its milestones, resources and costing plan.
A16: 12 | B16: Tasks | C16: My tasks page | D16: /my-tasks | E16: Everyone (own data) | F16: v1 base | G16: TSK-02 | H16: Each person sees exactly what is on their plate this week.
A17: 13 | B17: Tasks | C17: Manager assigns general tasks to reports (General & admin project) | D17: /team-tasks?tab=assign | E17: Administrator, CEO, CTO, Project Manager, HR Manager, Sales Manager | F17: v3 business processes | G17: TSK-01 | H17: Non-project work is tracked with the same discipline as project work.
A18: 14 | B18: Tasks | C18: Submit task for review with note and proof link | D18: Task drawer → Submit for review | E18: Everyone (own data) | F18: v3 business processes | G18: TSK-04 | H18: 'Done' means reviewed and accepted, not self-declared.
A19: 15 | B19: Tasks | C19: Delay reason captured when a task is late | D19: Task drawer → Submit for review | E19: Everyone (own data) | F19: v3 business processes | G19: TSK-05 | H19: Shows why work slips, so causes can be fixed.
A20: 16 | B20: Tasks | C20: Approve task with quality rating (1–5) | D20: /inbox; /team-tasks?tab=review; task drawer | E20: Administrator, CEO, CTO, Project Manager, HR Manager, Sales Manager | F20: v3 business processes | G20: TSK-06 | H20: Adds a quality score to on-time delivery for appraisals.
A21: 17 | B21: Tasks | C21: Send back with reason (review rounds) | D21: /inbox; task drawer | E21: Administrator, CEO, CTO, Project Manager, HR Manager, Sales Manager | F21: v3 business processes | G21: TSK-07 | H21: Rework is visible and counted.
A22: 18 | B22: Tasks | C22: Reschedule a task with reason (target revisions) | D22: Task drawer | E22: Administrator, CEO, CTO, Project Manager | F22: v3 business processes | G22: TSK-08 | H22: Every date change is explained and kept.
A23: 19 | B23: Tasks | C23: Timeliness: early / on time / late in working days | D23: Computed (task lists, performance, appraisals) | E23: Everyone (own data) | F23: v3 business processes | G23: TSK-09 | H23: One fair, consistent measure of delivery for everyone.
A24: 20 | B24: Tasks | C24: Team task monitoring and review queue | D24: /team-tasks?tab=team; /team-tasks?tab=review | E24: Administrator, CEO, CTO, Project Manager, HR Manager, Sales Manager | F24: v3 business processes | G24: TSK-10 | H24: Line managers see all their reports' work in one place.
A25: 21 | B25: Tasks | C25: Team and company delivery performance (by person / project) | D25: /team-tasks?tab=performance; /home | E25: Administrator, CEO, CTO, Project Manager, HR Manager | F25: v3 business processes | G25: TSK-11 | H25: Spot who needs help and which projects slip most.
A26: 22 | B26: Tasks | C26: Extra task tags: Feature, Improvement, Documentation, Support, Meeting | D26: Task drawer; /tasks filter | E26: Administrator, CEO, CTO, Project Manager | F26: v5 parity extras | H26: Work can be sliced by type, not only bugs.
A27: 23 | B27: Tasks | C27: Task visibility: employees see own/covering/reviewer tasks; managers, HR, admins and CXOs see all with employee filter and By-employee view | D27: /tasks | E27: Administrator, CEO, CTO, Project Manager, HR Manager, HR Executive, Sales Manager | F27: v7 workflows, documents & invoicing | H27: People see what concerns them; leaders see everything and filter by person.
A28: 24 | B28: Tasks | C28: Create task everywhere with full fields (reviewer, concerned manager, project, milestone, start/end, priority, depends on, watchers, acceptance criteria, attachments, recurrence) | D28: /tasks/new; Tasks; My tasks; Team tasks; WBS; dashboards | E28: Everyone (own data) | F28: v7 workflows, documents & invoicing | H28: One professional task form wherever work is assigned.
A29: 25 | B29: Time & attendance | C29: Apply for leave (employee self-service) | D29: /leave | E29: Everyone (own data) | F29: v3 business processes | G29: TIM-06 | H29: Employees request leave themselves instead of asking HR.
A30: 26 | B30: Time & attendance | C30: Approve, reject or cancel leave | D30: /leave; /inbox | E30: Administrator, CEO, CTO, Project Manager, HR Manager, Sales Manager | F30: v3 business processes | G30: TIM-07 | H30: Leave goes through the reporting manager with a record.
A31: 27 | B31: Time & attendance | C31: Leave policy and balances | D31: /leave (Policy) | E31: Administrator, CEO, HR Manager | F31: v3 business processes | G31: TIM-08 | H31: Entitlements and balances are calculated, not tracked in spreadsheets.
A32: 28 | B32: Time & attendance | C32: Team page: workload, timesheets and availability of reports | D32: /team | E32: Administrator, CEO, CTO, Project Manager, HR Manager, Sales Manager | F32: v1 base | H32: Managers see who is free, overloaded or behind on timesheets.
A33: 29 | B33: Approvals & governance | C33: Approvals inbox: every approval in one place | D33: /inbox | E33: All roles | F33: v3 business processes | G33: GOV-03 | H33: Managers clear timesheets, leave, expenses, POs, bills, tasks, documents and changes from one queue.
A34: 30 | B34: Approvals & governance | C34: Audit trail (who changed what, when) | D34: /audit | E34: Administrator, CEO, CTO | F34: v3 business processes | G34: GOV-04 | H34: Full accountability and ISO 9001 evidence.
A35: 31 | B35: Approvals & governance | C35: Goals & OKRs: company, team and personal objectives | D35: /okrs | E35: All roles (view: everyone); full: Administrator, CEO | F35: v3 business processes | G35: GOV-01 | H35: Links daily work to company goals.
